Workbook

Sheet MASANIELLO
A1: Masaniello Money Management System
K3: Open Blnc | L3: Close Blnc
A4: Description of Trade | B4: N° | C4: Result | D4: Trade Amount | E4: Return | F4: Current Portfolio | H4: Calculations | I4: Normale | K4: 127 | L4: 136
B5: 1 | C5: L | D5: =algoritmo!C3 -> 6.983906 | E5: =IF(algoritmo!D3=0,-D5,algoritmo!D3) -> -6.983906 | F5: =algoritmo!F3 -> 43.016094 | H5: Intial Capital | I5: 50
B6: 2 | C6: W | D6: =algoritmo!C4 -> 8.2374276 | E6: =IF(algoritmo!D4=0,-D6,algoritmo!D4) -> 10.708656 | F6: =algoritmo!F4 -> 53.72475 | H6: Total Trades | I6: 10
B7: 3 | C7: W | D7: =algoritmo!C5 -> 7.1047813 | E7: =IF(algoritmo!D5=0,-D7,algoritmo!D5) -> 9.2362157 | F7: =algoritmo!F5 -> 62.960966 | H7: Win Trades | I7: 4 | J7: =I7/I6 -> 0.4 | K7: Profit | L7: BDT
B8: 4 | C8: L | D8: =algoritmo!C6 -> 4.6688563 | E8: =IF(algoritmo!D6=0,-D8,algoritmo!D6) -> -4.6688563 | F8: =algoritmo!F6 -> 58.292109 | H8: Percentage | I8: 2.3 | K8: =L4-K4 -> 9 | L8: =K8*120 -> 1080
B9: =IF( B8<$I$6, B8+1, IF(C8="", " ", B8+1) ) -> 5 | C9: W | D9: =algoritmo!C7 -> 6.8835702 | E9: =IF(algoritmo!D7=0,-D9,algoritmo!D7) -> 8.9486412 | F9: =algoritmo!F7 -> 67.240751
B10: =IF( B9<$I$6, B9+1, IF(C9="", " ", B9+1) ) -> 6 | C10: L | D10: =algoritmo!C8 -> 3.1664423 | E10: =IF(algoritmo!D8=0,-D10,algoritmo!D8) -> -3.1664423 | F10: =algoritmo!F8 -> 64.074308 | H10: Wining Masaniello
B11: =IF( B10<$I$6, B10+1, IF(C10="", " ", B10+1) ) -> 7 | C11: L | D11: =algoritmo!C9 -> 5.6021671 | E11: =IF(algoritmo!D9=0,-D11,algoritmo!D9) -> -5.6021671 | F11: =algoritmo!F9 -> 58.472141 | H11: Capital Final | I11: =I5+I5*I12 -> 71.357125
B12: =IF( B11<$I$6, B11+1, IF(C11="", " ", B11+1) ) -> 8 | C12: L | D12: =algoritmo!C10 -> 9.9115264 | E12: =IF(algoritmo!D10=0,-D12,algoritmo!D10) -> -9.9115264 | F12: =algoritmo!F10 -> 48.560615 | H12: Ratio | I12: =algoritmo!$N$2-1 -> 0.42714251
B13: =IF( B12<$I$6, B12+1, IF(C12="", " ", B12+1) ) -> 9 | C13: W | D13: =algoritmo!C11 -> 17.535778 | E13: =IF(algoritmo!D11=0,-D13,algoritmo!D11) -> 22.796511 | F13: =algoritmo!F11 -> 71.357125 | H13: Win Profit | I13: =I11-I5 -> 21.357125
B14: =IF( B13<$I$6, B13+1, IF(C13="", " ", B13+1) ) -> 10 | C14: W | D14: =algoritmo!C12 -> 9.9670292 | E14: =IF(algoritmo!D12=0,-D14,algoritmo!D12) -> 12.957138 | F14: =algoritmo!F12 -> 84.314263
B15: 11 | C15: W | D15: =algoritmo!C13 -> 7.641389 | E15: =IF(algoritmo!D13=0,-D15,algoritmo!D13) -> 9.9338057 | F15: =algoritmo!F13 -> 94.248069 | H15: Sequence | I15: Number | J15: Percentage
B16: 12 | C16: W | D16: =algoritmo!C14 -> 4.3937987 | E16: =IF(algoritmo!D14=0,-D16,algoritmo!D14) -> 5.7119383 | F16: =algoritmo!F14 -> 99.960007 | H16: Events Win | I16: =COUNTIF(algoritmo!B2:B102,"=1") -> 10 | J16: =IF(I17+I16=0,"-",I16/(I17+I16)) -> 0.66666667
B17: 13 | C17: W | D17: =algoritmo!C15 -> 1.4436767 | E17: =IF(algoritmo!D15=0,-D17,algoritmo!D15) -> 1.8767797 | F17: =algoritmo!F15 -> 101.83679 | H17: Events Loose | I17: =COUNTIF(algoritmo!B2:B102,"=0") -> 5 | J17: =IF(I17+I16=0,"-",I17/(I17+I16)) -> 0.33333333
B18: 14 | C18: W | D18: =algoritmo!C16 -> 14.224371 | E18: =IF(algoritmo!D16=0,-D18,algoritmo!D16) -> 18.491682 | F18: =algoritmo!F16 -> 120.32847
B19: 15 | C19: W | D19: =algoritmo!C17 -> 10.905351 | E19: =IF(algoritmo!D17=0,-D19,algoritmo!D17) -> 14.176956 | F19: =algoritmo!F17 -> 134.50543

Sheet Sheet1
D4: Entry No: | E4: Win/Loss | F4: Initial Investment | G4: Trade Amount | H4: Profit % | I4: Return | J4: Total Investment
D5: 1 | E5: L | F5: 72 | G5: =F5*10% -> 7.2 | H5: 0.95 | I5: =H5*G5 -> 6.84 | J5: =IF(E5="W",F5+I5,F5-I5) -> 65.16
D6: 2 | E6: W | F6: =J5 -> 65.16 | G6: =F6*10% -> 6.516 | H6: =H5 -> 0.95 | I6: =H6*G6 -> 6.1902 | J6: =IF(E6="W",F6+I6,F6-I6) -> 71.3502
D7: 3 | E7: W | F7: =J6 -> 71.3502 | G7: =F7*10% -> 7.13502 | H7: =H6 -> 0.95 | I7: =H7*G7 -> 6.778269 | J7: =IF(E7="W",F7+I7,F7-I7) -> 78.128469
D8: 4 | E8: L | F8: =J7 -> 78.128469 | G8: =F8*10% -> 7.8128469 | H8: =H7 -> 0.95 | I8: =H8*G8 -> 7.4222046 | J8: =IF(E8="W",F8+I8,F8-I8) -> 70.706264
D9: 5 | E9: W | F9: =J8 -> 70.706264 | G9: =F9*10% -> 7.0706264 | H9: =H8 -> 0.95 | I9: =H9*G9 -> 6.7170951 | J9: =IF(E9="W",F9+I9,F9-I9) -> 77.42336
D10: 6 | E10: L | F10: =J9 -> 77.42336 | G10: =F10*10% -> 7.742336 | H10: =H9 -> 0.95 | I10: =H10*G10 -> 7.3552192 | J10: =IF(E10="W",F10+I10,F10-I10) -> 70.06814
D11: 7 | E11: W | F11: =J10 -> 70.06814 | G11: =F11*10% -> 7.006814 | H11: =H10 -> 0.95 | I11: =H11*G11 -> 6.6564733 | J11: =IF(E11="W",F11+I11,F11-I11) -> 76.724614
D12: 8 | E12: W | F12: =J11 -> 76.724614 | G12: =F12*10% -> 7.6724614 | H12: =H11 -> 0.95 | I12: =H12*G12 -> 7.2888383 | J12: =IF(E12="W",F12+I12,F12-I12) -> 84.013452
D13: 9 | E13: L | F13: =J12 -> 84.013452 | G13: =F13*10% -> 8.4013452 | H13: =H12 -> 0.95 | I13: =H13*G13 -> 7.9812779 | J13: =IF(E13="W",F13+I13,F13-I13) -> 76.032174
D14: 10 | E14: L | F14: =J13 -> 76.032174 | G14: =F14*10% -> 7.6032174 | H14: =H13 -> 0.95 | I14: =H14*G14 -> 7.2230565 | J14: =IF(E14="W",F14+I14,F14-I14) -> 68.809118
D15: 11 | E15: W | F15: =J14 -> 68.809118 | G15: =F15*10% -> 6.8809118 | H15: =H14 -> 0.95 | I15: =H15*G15 -> 6.5368662 | J15: =IF(E15="W",F15+I15,F15-I15) -> 75.345984
D16: 12 | E16: W | F16: =J15 -> 75.345984 | G16: =F16*10% -> 7.5345984 | H16: =H15 -> 0.95 | I16: =H16*G16 -> 7.1578685 | J16: =IF(E16="W",F16+I16,F16-I16) -> 82.503852
D17: 13 | E17: W | F17: =J16 -> 82.503852 | G17: =F17*10% -> 8.2503852 | H17: =H16 -> 0.95 | I17: =H17*G17 -> 7.837866 | J17: =IF(E17="W",F17+I17,F17-I17) -> 90.341718
... D27: 23 | E27: L | F27: =J26 -> 115.43003 | G27: =F27*10% -> 11.543003 | H27: =H26 -> 0.95 | I27: =H27*G27 -> 10.965853 | J27: =IF(E27="W",F27+I27,F27-I27) -> 104.46417

Sheet algoritmo
F1: Cassa | G1: Max | H1: Perdite | I1: Vincite | K1: eventi | L1: =MASANIELLO!$I$6 -> 10 | N1: 0 | O1: =IF(N1<$L$2,N1+1) -> 1 | P1: =IF(O1<$L$2,O1+1) -> 2 | Q1: =IF(P1<$L$2,P1+1) -> 3 | R1: =IF(Q1<$L$2,Q1+1) -> 4 | S1: =IF(R1<$L$2,R1+1) -> FALSE | T1: =IF(S1<$L$2,S1+1) -> FALSE | U1: =IF(T1<$L$2,T1+1) -> FALSE | V1: =IF(U1<$L$2,U1+1) -> FALSE | ... DJ1: =IF(DI1<$L$2,DI1+1) -> FALSE
A2: W-L | B2: W-L | C2: Investimento | D2: Ritorno | E2: Prelievo | F2: =MASANIELLO!$I$5 -> 50 | G2: =MASANIELLO!$I$5 -> 50 | H2: 0 | I2: 0 | K2: atesi | L2: =MASANIELLO!$I$7 -> 4 | M2: 0 | N2: =IF(N$1>$L$2, "", IF(N$1=$L$2, 1, IF($L$2-N$1=$L$1-$M2, $L$3^($L$1-$M2), ($L$3*N3*O3/(N3+($L$3-1)*O3) )))) -> 1.4271425 | O2: =IF(O$1>$L$2, "", IF(O$1=$L$2, 1, IF($L$2-O$1=$L$1-$M2, $L$3^($L$1-$M2), ($L$3*O3*P3/(O3+($L$3-1)*P3) )))) -> 1.1331904 | P2: =IF(P$1>$L$2, "", IF(P$1=$L$2, 1, IF($L$2-P$1=$L$1-$M2, $L$3^($L$1-$M2), ($L$3*P3*Q3/(P3+($L$3-1)*Q3) )))) -> 1.0297878 | Q2: =IF(Q$1>$L$2, "", IF(Q$1=$L$2, 1, IF($L$2-Q$1=$L$1-$M2, $L$3^($L$1-$M2), ($L$3*Q3*R3/(Q3+($L$3-1)*R3) )))) -> 1.0033389 | R2: =IF(R$1>$L$2, "", IF(R$1=$L$2, 1, IF($L$2-R$1=$L$1-$M2, $L$3^($L$1-$M2), ($L$3*R3*S3/(R3+($L$3-1)*S3) )))) -> 1 | S2: =IF(S$1>$L$2, "", IF(S$1=$L$2, 1, IF($L$2-S$1=$L$1-$M2, $L$3^($L$1-$M2), ($L$3*S3*T3/(S3+($L$3-1)*T3) )))) | T2: =IF(T$1>$L$2, "", IF(T$1=$L$2, 1, IF($L$2-T$1=$L$1-$M2, $L$3^($L$1-$M2), ($L$3*T3*U3/(T3+($L$3-1)*U3) )))) | U2: =IF(U$1>$L$2, "", IF(U$1=$L$2, 1, IF($L$2-U$1=$L$1-$M2, $L$3^($L$1-$M2), ($L$3*U3*V3/(U3+($L$3-1)*V3) )))) | ... DJ2: =IF(DJ$1>$L$2, "", IF(DJ$1=$L$2, 1, IF($L$2-DJ$1=$L$1-$M2, $L$3^($L$1-$M2), ($L$3*DJ3*DK3/(DJ3+($L$3-1)*DK3) ))))
A3: =MASANIELLO!C5 -> L | B3: =IF( OR(I2=$L$2,H2=1+$L$1-$L$2), "", IF(A3="l",0,IF(A3="w",1,"")) ) -> 0 | C3: =IF(OR(I2>=$L$2,D2=""),"",IF(ISERROR((1-$L$3*INDEX($N$2:$DJ$101,H2+I2+2,I2+2)/(INDEX($N$2:$DJ$101,H2+I2+2,I2+1)+($L$3-1)*(INDEX($N$2:$DJ$101,H2+I2+2,I2+2))))*$F2), $F2, (1-$L$3*INDEX($N$2:$DJ$101,H2+I2+2,I2+2)/(INDEX($N$2:$DJ$101,H2+I2+2,I2+1)+($L$3-1)*(INDEX($N$2:$DJ$101,H2+I2+2,I2+2))))*$F2 ) ) -> 6.983906 | D3: =IF(I2>=$L$2,"",IF(B3="", "", C3*($L$3-1)*B3) ) -> 0 | E3: =IF(B3="","",( D3-(IF((D3+F2)<=G2, D3, (G2-F2) )) )*(100-$L$5)/100 ) -> 0 | F3: =IF(I2>=$L$2,"",IF(B3="", "", IF(B3=0, F2-C3, IF( ((F2+D3)-G2)>=0, F2+(G2-F2)+((D3-(G2-F2))*$L$5/100), F2+D3 ) )) ) -> 43.016094 | G3: =IF(F3>G2, F3, G2) -> 50 | H3: =IF( $L$4=0, IF(I2+B3=$L$2,0,IF(B3=0,H2+1,H2)), IF( F3>=G2, 0, IF(B3=0,H2+1,H2) ) ) -> 1 | I3: =IF( $L$4=0, IF(I2+B3=$L$2,0,IF(B3=1,I2+1,I2)), IF( F3>=G2, 0, IF(B3=1,I2+1,I2) ) ) -> 0 | J3: =IF( B3="", "", IF( ISERROR((B3+I2)/(H2+I2+1)), 0, (B3+I2)/(H2+I2+1) ) ) -> 0 | K3: quota | L3: =MASANIELLO!$I$8 -> 2.3 | M3: =IF(M2<($L$1-1),M2+1) -> 1 | N3: =IF(N$1>$L$2, "", IF(N$1=$L$2, 1, IF($L$2-N$1=$L$1-$M3, $L$3^($L$1-$M3), ($L$3*N4*O4/(N4+($L$3-1)*O4) )))) -> 1.6588472 | O3: =IF(O$1>$L$2, "", IF(O$1=$L$2, 1, IF($L$2-O$1=$L$1-$M3, $L$3^($L$1-$M3), ($L$3*O4*P4/(O4+($L$3-1)*P4) )))) -> 1.207824 | P3: =IF(P$1>$L$2, "", IF(P$1=$L$2, 1, IF($L$2-P$1=$L$1-$M3, $L$3^($L$1-$M3), ($L$3*P4*Q4/(P4+($L$3-1)*Q4) )))) -> 1.0489306 | Q3: =IF(Q$1>$L$2, "", IF(Q$1=$L$2, 1, IF($L$2-Q$1=$L$1-$M3, $L$3^($L$1-$M3), ($L$3*Q4*R4/(Q4+($L$3-1)*R4) )))) -> 1.0059225 | R3: =IF(R$1>$L$2, "", IF(R$1=$L$2, 1, IF($L$2-R$1=$L$1-$M3, $L$3^($L$1-$M3), ($L$3*R4*S4/(R4+($L$3-1)*S4) )))) -> 1 | S3: =IF(S$1>$L$2, "", IF(S$1=$L$2, 1, IF($L$2-S$1=$L$1-$M3, $L$3^($L$1-$M3), ($L$3*S4*T4/(S4+($L$3-1)*T4) )))) | T3: =IF(T$1>$L$2, "", IF(T$1=$L$2, 1, IF($L$2-T$1=$L$1-$M3, $L$3^($L$1-$M3), ($L$3*T4*U4/(T4+($L$3-1)*U4) )))) | U3: =IF(U$1>$L$2, "", IF(U$1=$L$2, 1, IF($L$2-U$1=$L$1-$M3, $L$3^($L$1-$M3), ($L$3*U4*V4/(U4+($L$3-1)*V4) )))) | ... DJ3: =IF(DJ$1>$L$2, "", IF(DJ$1=$L$2, 1, IF($L$2-DJ$1=$L$1-$M3, $L$3^($L$1-$M3), ($L$3*DJ4*DK4/(DJ4+($L$3-1)*DK4) ))))
A4: =MASANIELLO!C6 -> W | B4: =IF( OR(I3=$L$2,H3=1+$L$1-$L$2), "", IF(A4="l",0,IF(A4="w",1,"")) ) -> 1 | C4: =IF(OR(I3>=$L$2,D3=""),"",IF(ISERROR((1-$L$3*INDEX($N$2:$DJ$101,H3+I3+2,I3+2)/(INDEX($N$2:$DJ$101,H3+I3+2,I3+1)+($L$3-1)*(INDEX($N$2:$DJ$101,H3+I3+2,I3+2))))*$F3), $F3, (1-$L$3*INDEX($N$2:$DJ$101,H3+I3+2,I3+2)/(INDEX($N$2:$DJ$101,H3+I3+2,I3+1)+($L$3-1)*(INDEX($N$2:$DJ$101,H3+I3+2,I3+2))))*$F3 ) ) -> 8.2374276 | D4: =IF(I3>=$L$2,"",IF(B4="", "", C4*($L$3-1)*B4) ) -> 10.708656 | E4: =IF(B4="","",( D4-(IF((D4+F3)<=G3, D4, (G3-F3) )) )*(100-$L$5)/100 ) -> 0 | F4: =IF(I3>=$L$2,"",IF(B4="", "", IF(B4=0, F3-C4, IF( ((F3+D4)-G3)>=0, F3+(G3-F3)+((D4-(G3-F3))*$L$5/100), F3+D4 ) )) ) -> 53.72475 | G4: =IF(F4>G3, F4, G3) -> 53.72475 | H4: =IF( $L$4=0, IF(I3+B4=$L$2,0,IF(B4=0,H3+1,H3)), IF( F4>=G3, 0, IF(B4=0,H3+1,H3) ) ) -> 1 | I4: =IF( $L$4=0, IF(I3+B4=$L$2,0,IF(B4=1,I3+1,I3)), IF( F4>=G3, 0, IF(B4=1,I3+1,I3) ) ) -> 1 | J4: =IF( B4="", "", IF( ISERROR((B4+I3)/(H3+I3+1)), 0, (B4+I3)/(H3+I3+1) ) ) -> 0.5 | K4: Masaniello tippo | L4: =IF(MASANIELLO!I4="normale", 0,1) -> 0 | M4: =IF(M3<($L$1-1),M3+1) -> 2 | N4: =IF(N$1>$L$2, "", IF(N$1=$L$2, 1, IF($L$2-N$1=$L$1-$M4, $L$3^($L$1-$M4), ($L$3*N5*O5/(N5+($L$3-1)*O5) )))) -> 2.0517499 | O4: =IF(O$1>$L$2, "", IF(O$1=$L$2, 1, IF($L$2-O$1=$L$1-$M4, $L$3^($L$1-$M4), ($L$3*O5*P5/(O5+($L$3-1)*P5) )))) -> 1.3281984 | P4: =IF(P$1>$L$2, "", IF(P$1=$L$2, 1, IF($L$2-P$1=$L$1-$M4, $L$3^($L$1-$M4), ($L$3*P5*Q5/(P5+($L$3-1)*Q5) )))) -> 1.0805186 | Q4: =IF(Q$1>$L$2, "", IF(Q$1=$L$2, 1, IF($L$2-Q$1=$L$1-$M4, $L$3^($L$1-$M4), ($L$3*Q5*R5/(Q5+($L$3-1)*R5) )))) -> 1.0105262 | R4: =IF(R$1>$L$2, "", IF(R$1=$L$2, 1, IF($L$2-R$1=$L$1-$M4, $L$3^($L$1-$M4), ($L$3*R5*S5/(R5+($L$3-1)*S5) )))) -> 1 | S4: =IF(S$1>$L$2, "", IF(S$1=$L$2, 1, IF($L$2-S$1=$L$1-$M4, $L$3^($L$1-$M4), ($L$3*S5*T5/(S5+($L$3-1)*T5) )))) | T4: =IF(T$1>$L$2, "", IF(T$1=$L$2, 1, IF($L$2-T$1=$L$1-$M4, $L$3^($L$1-$M4), ($L$3*T5*U5/(T5+($L$3-1)*U5) )))) | U4: =IF(U$1>$L$2, "", IF(U$1=$L$2, 1, IF($L$2-U$1=$L$1-$M4, $L$3^($L$1-$M4), ($L$3*U5*V5/(U5+($L$3-1)*V5) )))) | ... DJ4: =IF(DJ$1>$L$2, "", IF(DJ$1=$L$2, 1, IF($L$2-DJ$1=$L$1-$M4, $L$3^($L$1-$M4), ($L$3*DJ5*DK5/(DJ5+($L$3-1)*DK5) ))))
A5: =MASANIELLO!C7 -> W | B5: =IF( OR(I4=$L$2,H4=1+$L$1-$L$2), "", IF(A5="l",0,IF(A5="w",1,"")) ) -> 1 | C5: =IF(OR(I4>=$L$2,D4=""),"",IF(ISERROR((1-$L$3*INDEX($N$2:$DJ$101,H4+I4+2,I4+2)/(INDEX($N$2:$DJ$101,H4+I4+2,I4+1)+($L$3-1)*(INDEX($N$2:$DJ$101,H4+I4+2,I4+2))))*$F4), $F4, (1-$L$3*INDEX($N$2:$DJ$101,H4+I4+2,I4+2)/(INDEX($N$2:$DJ$101,H4+I4+2,I4+1)+($L$3-1)*(INDEX($N$2:$DJ$101,H4+I4+2,I4+2))))*$F4 ) ) -> 7.1047813 | D5: =IF(I4>=$L$2,"",IF(B5="", "", C5*($L$3-1)*B5) ) -> 9.2362157 | E5: =IF(B5="","",( D5-(IF((D5+F4)<=G4, D5, (G4-F4) )) )*(100-$L$5)/100 ) -> 0 | F5: =IF(I4>=$L$2,"",IF(B5="", "", IF(B5=0, F4-C5, IF( ((F4+D5)-G4)>=0, F4+(G4-F4)+((D5-(G4-F4))*$L$5/100), F4+D5 ) )) ) -> 62.960966 | G5: =IF(F5>G4, F5, G4) -> 62.960966 | H5: =IF( $L$4=0, IF(I4+B5=$L$2,0,IF(B5=0,H4+1,H4)), IF( F5>=G4, 0, IF(B5=0,H4+1,H4) ) ) -> 1 | I5: =IF( $L$4=0, IF(I4+B5=$L$2,0,IF(B5=1,I4+1,I4)), IF( F5>=G4, 0, IF(B5=1,I4+1,I4) ) ) -> 2 | J5: =IF( B5="", "", IF( ISERROR((B5+I4)/(H4+I4+1)), 0, (B5+I4)/(H4+I4+1) ) ) -> 0.66666667 | K5: % da reinvestire | L5: =IF(L4=1,MASANIELLO!#REF!,100) -> 100 | M5: =IF(M4<($L$1-1),M4+1) -> 3 | N5: =IF(N$1>$L$2, "", IF(N$1=$L$2, 1, IF($L$2-N$1=$L$1-$M5, $L$3^($L$1-$M5), ($L$3*N6*O6/(N6+($L$3-1)*O6) )))) -> 2.7797897 | O5: =IF(O$1>$L$2, "", IF(O$1=$L$2, 1, IF($L$2-O$1=$L$1-$M5, $L$3^($L$1-$M5), ($L$3*O6*P6/(O6+($L$3-1)*P6) )))) -> 1.5306129 | P5: =IF(P$1>$L$2, "", IF(P$1=$L$2, 1, IF($L$2-P$1=$L$1-$M5, $L$3^($L$1-$M5), ($L$3*P6*Q6/(P6+($L$3-1)*Q6) )))) -> 1.133355 | Q5: =IF(Q$1>$L$2, "", IF(Q$1=$L$2, 1, IF($L$2-Q$1=$L$1-$M5, $L$3^($L$1-$M5), ($L$3*Q6*R6/(Q6+($L$3-1)*R6) )))) -> 1.0187753 | R5: =IF(R$1>$L$2, "", IF(R$1=$L$2, 1, IF($L$2-R$1=$L$1-$M5, $L$3^($L$1-$M5), ($L$3*R6*S6/(R6+($L$3-1)*S6) )))) -> 1 | S5: =IF(S$1>$L$2, "", IF(S$1=$L$2, 1, IF($L$2-S$1=$L$1-$M5, $L$3^($L$1-$M5), ($L$3*S6*T6/(S6+($L$3-1)*T6) )))) | T5: =IF(T$1>$L$2, "", IF(T$1=$L$2, 1, IF($L$2-T$1=$L$1-$M5, $L$3^($L$1-$M5), ($L$3*T6*U6/(T6+($L$3-1)*U6) )))) | U5: =IF(U$1>$L$2, "", IF(U$1=$L$2, 1, IF($L$2-U$1=$L$1-$M5, $L$3^($L$1-$M5), ($L$3*U6*V6/(U6+($L$3-1)*V6) )))) | ... DJ5: =IF(DJ$1>$L$2, "", IF(DJ$1=$L$2, 1, IF($L$2-DJ$1=$L$1-$M5, $L$3^($L$1-$M5), ($L$3*DJ6*DK6/(DJ6+($L$3-1)*DK6) ))))
A6: =MASANIELLO!C8 -> L | B6: =IF( OR(I5=$L$2,H5=1+$L$1-$L$2), "", IF(A6="l",0,IF(A6="w",1,"")) ) -> 0 | C6: =IF(OR(I5>=$L$2,D5=""),"",IF(ISERROR((1-$L$3*INDEX($N$2:$DJ$101,H5+I5+2,I5+2)/(INDEX($N$2:$DJ$101,H5+I5+2,I5+1)+($L$3-1)*(INDEX($N$2:$DJ$101,H5+I5+2,I5+2))))*$F5), $F5, (1-$L$3*INDEX($N$2:$DJ$101,H5+I5+2,I5+2)/(INDEX($N$2:$DJ$101,H5+I5+2,I5+1)+($L$3-1)*(INDEX($N$2:$DJ$101,H5+I5+2,I5+2))))*$F5 ) ) -> 4.6688563 | D6: =IF(I5>=$L$2,"",IF(B6="", "", C6*($L$3-1)*B6) ) -> 0 | E6: =IF(B6="","",( D6-(IF((D6+F5)<=G5, D6, (G5-F5) )) )*(100-$L$5)/100 ) -> 0 | F6: =IF(I5>=$L$2,"",IF(B6="", "", IF(B6=0, F5-C6, IF( ((F5+D6)-G5)>=0, F5+(G5-F5)+((D6-(G5-F5))*$L$5/100), F5+D6 ) )) ) -> 58.292109 | G6: =IF(F6>G5, F6, G5) -> 62.960966 | H6: =IF( $L$4=0, IF(I5+B6=$L$2,0,IF(B6=0,H5+1,H5)), IF( F6>=G5, 0, IF(B6=0,H5+1,H5) ) ) -> 2 | I6: =IF( $L$4=0, IF(I5+B6=$L$2,0,IF(B6=1,I5+1,I5)), IF( F6>=G5, 0, IF(B6=1,I5+1,I5) ) ) -> 2 | J6: =IF( B6="", "", IF( ISERROR((B6+I5)/(H5+I5+1)), 0, (B6+I5)/(H5+I5+1) ) ) -> 0.5 | M6: =IF(M5<($L$1-1),M5+1) -> 4 | N6: =IF(N$1>$L$2, "", IF(N$1=$L$2, 1, IF($L$2-N$1=$L$1-$M6, $L$3^($L$1-$M6), ($L$3*N7*O7/(N7+($L$3-1)*O7) )))) -> 4.3348723 | O6: =IF(O$1>$L$2, "", IF(O$1=$L$2, 1, IF($L$2-O$1=$L$1-$M6, $L$3^($L$1-$M6), ($L$3*O7*P7/(O7+($L$3-1)*P7) )))) -> 1.8957087 | P6: =IF(P$1>$L$2, "", IF(P$1=$L$2, 1, IF($L$2-P$1=$L$1-$M6, $L$3^($L$1-$M6), ($L$3*P7*Q7/(P7+($L$3-1)*Q7) )))) -> 1.2241301 | Q6: =IF(Q$1>$L$2, "", IF(Q$1=$L$2, 1, IF($L$2-Q$1=$L$1-$M6, $L$3^($L$1-$M6), ($L$3*Q7*R7/(Q7+($L$3-1)*R7) )))) -> 1.0337046 | R6: =IF(R$1>$L$2, "", IF(R$1=$L$2, 1, IF($L$2-R$1=$L$1-$M6, $L$3^($L$1-$M6), ($L$3*R7*S7/(R7+($L$3-1)*S7) )))) -> 1 | S6: =IF(S$1>$L$2, "", IF(S$1=$L$2, 1, IF($L$2-S$1=$L$1-$M6, $L$3^($L$1-$M6), ($L$3*S7*T7/(S7+($L$3-1)*T7) )))) | T6: =IF(T$1>$L$2, "", IF(T$1=$L$2, 1, IF($L$2-T$1=$L$1-$M6, $L$3^($L$1-$M6), ($L$3*T7*U7/(T7+($L$3-1)*U7) )))) | U6: =IF(U$1>$L$2, "", IF(U$1=$L$2, 1, IF($L$2-U$1=$L$1-$M6, $L$3^($L$1-$M6), ($L$3*U7*V7/(U7+($L$3-1)*V7) )))) | ... DJ6: =IF(DJ$1>$L$2, "", IF(DJ$1=$L$2, 1, IF($L$2-DJ$1=$L$1-$M6, $L$3^($L$1-$M6), ($L$3*DJ7*DK7/(DJ7+($L$3-1)*DK7) ))))
A7: =MASANIELLO!C9 -> W | B7: =IF( OR(I6=$L$2,H6=1+$L$1-$L$2), "", IF(A7="l",0,IF(A7="w",1,"")) ) -> 1 | C7: =IF(OR(I6>=$L$2,D6=""),"",IF(ISERROR((1-$L$3*INDEX($N$2:$DJ$101,H6+I6+2,I6+2)/(INDEX($N$2:$DJ$101,H6+I6+2,I6+1)+($L$3-1)*(INDEX($N$2:$DJ$101,H6+I6+2,I6+2))))*$F6), $F6, (1-$L$3*INDEX($N$2:$DJ$101,H6+I6+2,I6+2)/(INDEX($N$2:$DJ$101,H6+I6+2,I6+1)+($L$3-1)*(INDEX($N$2:$DJ$101,H6+I6+2,I6+2))))*$F6 ) ) -> 6.8835702 | D7: =IF(I6>=$L$2,"",IF(B7="", "", C7*($L$3-1)*B7) ) -> 8.9486412 | E7: =IF(B7="","",( D7-(IF((D7+F6)<=G6, D7, (G6-F6) )) )*(100-$L$5)/100 ) -> 0 | F7: =IF(I6>=$L$2,"",IF(B7="", "", IF(B7=0, F6-C7, IF( ((F6+D7)-G6)>=0, F6+(G6-F6)+((D7-(G6-F6))*$L$5/100), F6+D7 ) )) ) -> 67.240751 | G7: =IF(F7>G6, F7, G6) -> 67.240751 | H7: =IF( $L$4=0, IF(I6+B7=$L$2,0,IF(B7=0,H6+1,H6)), IF( F7>=G6, 0, IF(B7=0,H6+1,H6) ) ) -> 2 | I7: =IF( $L$4=0, IF(I6+B7=$L$2,0,IF(B7=1,I6+1,I6)), IF( F7>=G6, 0, IF(B7=1,I6+1,I6) ) ) -> 3 | J7: =IF( B7="", "", IF( ISERROR((B7+I6)/(H6+I6+1)), 0, (B7+I6)/(H6+I6+1) ) ) -> 0.6 | M7: =IF(M6<($L$1-1),M6+1) -> 5 | N7: =IF(N$1>$L$2, "", IF(N$1=$L$2, 1, IF($L$2-N$1=$L$1-$M7, $L$3^($L$1-$M7), ($L$3*N8*O8/(N8+($L$3-1)*O8) )))) -> 8.5817907 | O7: =IF(O$1>$L$2, "", IF(O$1=$L$2, 1, IF($L$2-O$1=$L$1-$M7, $L$3^($L$1-$M7), ($L$3*O8*P8/(O8+($L$3-1)*P8) )))) -> 2.6378455 | P7: =IF(P$1>$L$2, "", IF(P$1=$L$2, 1, IF($L$2-P$1=$L$1-$M7, $L$3^($L$1-$M7), ($L$3*P8*Q8/(P8+($L$3-1)*Q8) )))) -> 1.3880403 | Q7: =IF(Q$1>$L$2, "", IF(Q$1=$L$2, 1, IF($L$2-Q$1=$L$1-$M7, $L$3^($L$1-$M7), ($L$3*Q8*R8/(Q8+($L$3-1)*R8) )))) -> 1.0612185 | R7: =IF(R$1>$L$2, "", IF(R$1=$L$2, 1, IF($L$2-R$1=$L$1-$M7, $L$3^($L$1-$M7), ($L$3*R8*S8/(R8+($L$3-1)*S8) )))) -> 1 | S7: =IF(S$1>$L$2, "", IF(S$1=$L$2, 1, IF($L$2-S$1=$L$1-$M7, $L$3^($L$1-$M7), ($L$3*S8*T8/(S8+($L$3-1)*T8) )))) | T7: =IF(T$1>$L$2, "", IF(T$1=$L$2, 1, IF($L$2-T$1=$L$1-$M7, $L$3^($L$1-$M7), ($L$3*T8*U8/(T8+($L$3-1)*U8) )))) | U7: =IF(U$1>$L$2, "", IF(U$1=$L$2, 1, IF($L$2-U$1=$L$1-$M7, $L$3^($L$1-$M7), ($L$3*U8*V8/(U8+($L$3-1)*V8) )))) | ... DJ7: =IF(DJ$1>$L$2, "", IF(DJ$1=$L$2, 1, IF($L$2-DJ$1=$L$1-$M7, $L$3^($L$1-$M7), ($L$3*DJ8*DK8/(DJ8+($L$3-1)*DK8) ))))
A8: =MASANIELLO!C10 -> L | B8: =IF( OR(I7=$L$2,H7=1+$L$1-$L$2), "", IF(A8="l",0,IF(A8="w",1,"")) ) -> 0 | C8: =IF(OR(I7>=$L$2,D7=""),"",IF(ISERROR((1-$L$3*INDEX($N$2:$DJ$101,H7+I7+2,I7+2)/(INDEX($N$2:$DJ$101,H7+I7+2,I7+1)+($L$3-1)*(INDEX($N$2:$DJ$101,H7+I7+2,I7+2))))*$F7), $F7, (1-$L$3*INDEX($N$2:$DJ$101,H7+I7+2,I7+2)/(INDEX($N$2:$DJ$101,H7+I7+2,I7+1)+($L$3-1)*(INDEX($N$2:$DJ$101,H7+I7+2,I7+2))))*$F7 ) ) -> 3.1664423 | D8: =IF(I7>=$L$2,"",IF(B8="", "", C8*($L$3-1)*B8) ) -> 0 | E8: =IF(B8="","",( D8-(IF((D8+F7)<=G7, D8, (G7-F7) )) )*(100-$L$5)/100 ) -> 0 | F8: =IF(I7>=$L$2,"",IF(B8="", "", IF(B8=0, F7-C8, IF( ((F7+D8)-G7)>=0, F7+(G7-F7)+((D8-(G7-F7))*$L$5/100), F7+D8 ) )) ) -> 64.074308 | G8: =IF(F8>G7, F8, G7) -> 67.240751 | H8: =IF( $L$4=0, IF(I7+B8=$L$2,0,IF(B8=0,H7+1,H7)), IF( F8>=G7, 0, IF(B8=0,H7+1,H7) ) ) -> 3 | I8: =IF( $L$4=0, IF(I7+B8=$L$2,0,IF(B8=1,I7+1,I7)), IF( F8>=G7, 0, IF(B8=1,I7+1,I7) ) ) -> 3 | J8: =IF( B8="", "", IF( ISERROR((B8+I7)/(H7+I7+1)), 0, (B8+I7)/(H7+I7+1) ) ) -> 0.5 | M8: =IF(M7<($L$1-1),M7+1) -> 6 | N8: =IF(N$1>$L$2, "", IF(N$1=$L$2, 1, IF($L$2-N$1=$L$1-$M8, $L$3^($L$1-$M8), ($L$3*N9*O9/(N9+($L$3-1)*O9) )))) -> 27.9841 | O8: =IF(O$1>$L$2, "", IF(O$1=$L$2, 1, IF($L$2-O$1=$L$1-$M8, $L$3^($L$1-$M8), ($L$3*O9*P9/(O9+($L$3-1)*P9) )))) -> 4.5135645 | P8: =IF(P$1>$L$2, "", IF(P$1=$L$2, 1, IF($L$2-P$1=$L$1-$M8, $L$3^($L$1-$M8), ($L$3*P9*Q9/(P9+($L$3-1)*Q9) )))) -> 1.7126132 | Q8: =IF(Q$1>$L$2, "", IF(Q$1=$L$2, 1, IF($L$2-Q$1=$L$1-$M8, $L$3^($L$1-$M8), ($L$3*Q9*R9/(Q9+($L$3-1)*R9) )))) -> 1.1136621 | R8: =IF(R$1>$L$2, "", IF(R$1=$L$2, 1, IF($L$2-R$1=$L$1-$M8, $L$3^($L$1-$M8), ($L$3*R9*S9/(R9+($L$3-1)*S9) )))) -> 1 | S8: =IF(S$1>$L$2, "", IF(S$1=$L$2, 1, IF($L$2-S$1=$L$1-$M8, $L$3^($L$1-$M8), ($L$3*S9*T9/(S9+($L$3-1)*T9) )))) | T8: =IF(T$1>$L$2, "", IF(T$1=$L$2, 1, IF($L$2-T$1=$L$1-$M8, $L$3^($L$1-$M8), ($L$3*T9*U9/(T9+($L$3-1)*U9) )))) | U8: =IF(U$1>$L$2, "", IF(U$1=$L$2, 1, IF($L$2-U$1=$L$1-$M8, $L$3^($L$1-$M8), ($L$3*U9*V9/(U9+($L$3-1)*V9) )))) | ... DJ8: =IF(DJ$1>$L$2, "", IF(DJ$1=$L$2, 1, IF($L$2-DJ$1=$L$1-$M8, $L$3^($L$1-$M8), ($L$3*DJ9*DK9/(DJ9+($L$3-1)*DK9) ))))
A9: =MASANIELLO!C11 -> L | B9: =IF( OR(I8=$L$2,H8=1+$L$1-$L$2), "", IF(A9="l",0,IF(A9="w",1,"")) ) -> 0 | C9: =IF(OR(I8>=$L$2,D8=""),"",IF(ISERROR((1-$L$3*INDEX($N$2:$DJ$101,H8+I8+2,I8+2)/(INDEX($N$2:$DJ$101,H8+I8+2,I8+1)+($L$3-1)*(INDEX($N$2:$DJ$101,H8+I8+2,I8+2))))*$F8), $F8, (1-$L$3*INDEX($N$2:$DJ$101,H8+I8+2,I8+2)/(INDEX($N$2:$DJ$101,H8+I8+2,I8+1)+($L$3-1)*(INDEX($N$2:$DJ$101,H8+I8+2,I8+2))))*$F8 ) ) -> 5.6021671 | D9: =IF(I8>=$L$2,"",IF(B9="", "", C9*($L$3-1)*B9) ) -> 0 | E9: =IF(B9="","",( D9-(IF((D9+F8)<=G8, D9, (G8-F8) )) )*(100-$L$5)/100 ) -> 0 | F9: =IF(I8>=$L$2,"",IF(B9="", "", IF(B9=0, F8-C9, IF( ((F8+D9)-G8)>=0, F8+(G8-F8)+((D9-(G8-F8))*$L$5/100), F8+D9 ) )) ) -> 58.472141 | G9: =IF(F9>G8, F9, G8) -> 67.240751 | H9: =IF( $L$4=0, IF(I8+B9=$L$2,0,IF(B9=0,H8+1,H8)), IF( F9>=G8, 0, IF(B9=0,H8+1,H8) ) ) -> 4 | I9: =IF( $L$4=0, IF(I8+B9=$L$2,0,IF(B9=1,I8+1,I8)), IF( F9>=G8, 0, IF(B9=1,I8+1,I8) ) ) -> 3 | J9: =IF( B9="", "", IF( ISERROR((B9+I8)/(H8+I8+1)), 0, (B9+I8)/(H8+I8+1) ) ) -> 0.42857143 | M9: =IF(M8<($L$1-1),M8+1) -> 7 | N9: =IF(N$1>$L$2, "", IF(N$1=$L$2, 1, IF($L$2-N$1=$L$1-$M9, $L$3^($L$1-$M9), ($L$3*N10*O10/(N10+($L$3-1)*O10) )))) -> #DIV/0! | O9: =IF(O$1>$L$2, "", IF(O$1=$L$2, 1, IF($L$2-O$1=$L$1-$M9, $L$3^($L$1-$M9), ($L$3*O10*P10/(O10+($L$3-1)*P10) )))) -> 12.167 | P9: =IF(P$1>$L$2, "", IF(P$1=$L$2, 1, IF($L$2-P$1=$L$1-$M9, $L$3^($L$1-$M9), ($L$3*P10*Q10/(P10+($L$3-1)*Q10) )))) -> 2.4830612 | Q9: =IF(Q$1>$L$2, "", IF(Q$1=$L$2, 1, IF($L$2-Q$1=$L$1-$M9, $L$3^($L$1-$M9), ($L$3*Q10*R10/(Q10+($L$3-1)*R10) )))) -> 1.2203611 | R9: =IF(R$1>$L$2, "", IF(R$1=$L$2, 1, IF($L$2-R$1=$L$1-$M9, $L$3^($L$1-$M9), ($L$3*R10*S10/(R10+($L$3-1)*S10) )))) -> 1 | S9: =IF(S$1>$L$2, "", IF(S$1=$L$2, 1, IF($L$2-S$1=$L$1-$M9, $L$3^($L$1-$M9), ($L$3*S10*T10/(S10+($L$3-1)*T10) )))) | T9: =IF(T$1>$L$2, "", IF(T$1=$L$2, 1, IF($L$2-T$1=$L$1-$M9, $L$3^($L$1-$M9), ($L$3*T10*U10/(T10+($L$3-1)*U10) )))) | U9: =IF(U$1>$L$2, "", IF(U$1=$L$2, 1, IF($L$2-U$1=$L$1-$M9, $L$3^($L$1-$M9), ($L$3*U10*V10/(U10+($L$3-1)*V10) )))) | ... DJ9: =IF(DJ$1>$L$2, "", IF(DJ$1=$L$2, 1, IF($L$2-DJ$1=$L$1-$M9, $L$3^($L$1-$M9), ($L$3*DJ10*DK10/(DJ10+($L$3-1)*DK10) ))))
A10: =MASANIELLO!C12 -> L | B10: =IF( OR(I9=$L$2,H9=1+$L$1-$L$2), "", IF(A10="l",0,IF(A10="w",1,"")) ) -> 0 | C10: =IF(OR(I9>=$L$2,D9=""),"",IF(ISERROR((1-$L$3*INDEX($N$2:$DJ$101,H9+I9+2,I9+2)/(INDEX($N$2:$DJ$101,H9+I9+2,I9+1)+($L$3-1)*(INDEX($N$2:$DJ$101,H9+I9+2,I9+2))))*$F9), $F9, (1-$L$3*INDEX($N$2:$DJ$101,H9+I9+2,I9+2)/(INDEX($N$2:$DJ$101,H9+I9+2,I9+1)+($L$3-1)*(INDEX($N$2:$DJ$101,H9+I9+2,I9+2))))*$F9 ) ) -> 9.9115264 | D10: =IF(I9>=$L$2,"",IF(B10="", "", C10*($L$3-1)*B10) ) -> 0 | E10: =IF(B10="","",( D10-(IF((D10+F9)<=G9, D10, (G9-F9) )) )*(100-$L$5)/100 ) -> 0 | F10: =IF(I9>=$L$2,"",IF(B10="", "", IF(B10=0, F9-C10, IF( ((F9+D10)-G9)>=0, F9+(G9-F9)+((D10-(G9-F9))*$L$5/100), F9+D10 ) )) ) -> 48.560615 | G10: =IF(F10>G9, F10, G9) -> 67.240751 | H10: =IF( $L$4=0, IF(I9+B10=$L$2,0,IF(B10=0,H9+1,H9)), IF( F10>=G9, 0, IF(B10=0,H9+1,H9) ) ) -> 5 | I10: =IF( $L$4=0, IF(I9+B10=$L$2,0,IF(B10=1,I9+1,I9)), IF( F10>=G9, 0, IF(B10=1,I9+1,I9) ) ) -> 3 | J10: =IF( B10="", "", IF( ISERROR((B10+I9)/(H9+I9+1)), 0, (B10+I9)/(H9+I9+1) ) ) -> 0.375 | M10: =IF(M9<($L$1-1),M9+1) -> 8 | N10: =IF(N$1>$L$2, "", IF(N$1=$L$2, 1, IF($L$2-N$1=$L$1-$M10, $L$3^($L$1-$M10), ($L$3*N11*O11/(N11+($L$3-1)*O11) )))) -> #DIV/0! | O10: =IF(O$1>$L$2, "", IF(O$1=$L$2, 1, IF($L$2-O$1=$L$1-$M10, $L$3^($L$1-$M10), ($L$3*O11*P11/(O11+($L$3-1)*P11) )))) -> #DIV/0! | P10: =IF(P$1>$L$2, "", IF(P$1=$L$2, 1, IF($L$2-P$1=$L$1-$M10, $L$3^($L$1-$M10), ($L$3*P11*Q11/(P11+($L$3-1)*Q11) )))) -> 5.29 | Q10: =IF(Q$1>$L$2, "", IF(Q$1=$L$2, 1, IF($L$2-Q$1=$L$1-$M10, $L$3^($L$1-$M10), ($L$3*Q11*R11/(Q11+($L$3-1)*R11) )))) -> 1.4694444 | R10: =IF(R$1>$L$2, "", IF(R$1=$L$2, 1, IF($L$2-R$1=$L$1-$M10, $L$3^($L$1-$M10), ($L$3*R11*S11/(R11+($L$3-1)*S11) )))) -> 1 | S10: =IF(S$1>$L$2, "", IF(S$1=$L$2, 1, IF($L$2-S$1=$L$1-$M10, $L$3^($L$1-$M10), ($L$3*S11*T11/(S11+($L$3-1)*T11) )))) | T10: =IF(T$1>$L$2, "", IF(T$1=$L$2, 1, IF($L$2-T$1=$L$1-$M10, $L$3^($L$1-$M10), ($L$3*T11*U11/(T11+($L$3-1)*U11) )))) | U10: =IF(U$1>$L$2, "", IF(U$1=$L$2, 1, IF($L$2-U$1=$L$1-$M10, $L$3^($L$1-$M10), ($L$3*U11*V11/(U11+($L$3-1)*V11) )))) | ... DJ10: =IF(DJ$1>$L$2, "", IF(DJ$1=$L$2, 1, IF($L$2-DJ$1=$L$1-$M10, $L$3^($L$1-$M10), ($L$3*DJ11*DK11/(DJ11+($L$3-1)*DK11) ))))
A11: =MASANIELLO!C13 -> W | B11: =IF( OR(I10=$L$2,H10=1+$L$1-$L$2), "", IF(A11="l",0,IF(A11="w",1,"")) ) -> 1 | C11: =IF(OR(I10>=$L$2,D10=""),"",IF(ISERROR((1-$L$3*INDEX($N$2:$DJ$101,H10+I10+2,I10+2)/(INDEX($N$2:$DJ$101,H10+I10+2,I10+1)+($L$3-1)*(INDEX($N$2:$DJ$101,H10+I10+2,I10+2))))*$F10), $F10, (1-$L$3*INDEX($N$2:$DJ$101,H10+I10+2,I10+2)/(INDEX($N$2:$DJ$101,H10+I10+2,I10+1)+($L$3-1)*(INDEX($N$2:$DJ$101,H10+I10+2,I10+2))))*$F10 ) ) -> 17.535778 | D11: =IF(I10>=$L$2,"",IF(B11="", "", C11*($L$3-1)*B11) ) -> 22.796511 | E11: =IF(B11="","",( D11-(IF((D11+F10)<=G10, D11, (G10-F10) )) )*(100-$L$5)/100 ) -> 0 | F11: =IF(I10>=$L$2,"",IF(B11="", "", IF(B11=0, F10-C11, IF( ((F10+D11)-G10)>=0, F10+(G10-F10)+((D11-(G10-F10))*$L$5/100), F10+D11 ) )) ) -> 71.357125 | G11: =IF(F11>G10, F11, G10) -> 71.357125 | H11: =IF( $L$4=0, IF(I10+B11=$L$2,0,IF(B11=0,H10+1,H10)), IF( F11>=G10, 0, IF(B11=0,H10+1,H10) ) ) -> 0 | I11: =IF( $L$4=0, IF(I10+B11=$L$2,0,IF(B11=1,I10+1,I10)), IF( F11>=G10, 0, IF(B11=1,I10+1,I10) ) ) -> 0 | J11: =IF( B11="", "", IF( ISERROR((B11+I10)/(H10+I10+1)), 0, (B11+I10)/(H10+I10+1) ) ) -> 0.44444444 | M11: =IF(M10<($L$1-1),M10+1) -> 9 | N11: =IF(N$1>$L$2, "", IF(N$1=$L$2, 1, IF($L$2-N$1=$L$1-$M11, $L$3^($L$1-$M11), ($L$3*N12*O12/(N12+($L$3-1)*O12) )))) -> #DIV/0! | O11: =IF(O$1>$L$2, "", IF(O$1=$L$2, 1, IF($L$2-O$1=$L$1-$M11, $L$3^($L$1-$M11), ($L$3*O12*P12/(O12+($L$3-1)*P12) )))) -> #DIV/0! | P11: =IF(P$1>$L$2, "", IF(P$1=$L$2, 1, IF($L$2-P$1=$L$1-$M11, $L$3^($L$1-$M11), ($L$3*P12*Q12/(P12+($L$3-1)*Q12) )))) -> #DIV/0! | Q11: =IF(Q$1>$L$2, "", IF(Q$1=$L$2, 1, IF($L$2-Q$1=$L$1-$M11, $L$3^($L$1-$M11), ($L$3*Q12*R12/(Q12+($L$3-1)*R12) )))) -> 2.3 | R11: =IF(R$1>$L$2, "", IF(R$1=$L$2, 1, IF($L$2-R$1=$L$1-$M11, $L$3^($L$1-$M11), ($L$3*R12*S12/(R12+($L$3-1)*S12) )))) -> 1 | S11: =IF(S$1>$L$2, "", IF(S$1=$L$2, 1, IF($L$2-S$1=$L$1-$M11, $L$3^($L$1-$M11), ($L$3*S12*T12/(S12+($L$3-1)*T12) )))) | T11: =IF(T$1>$L$2, "", IF(T$1=$L$2, 1, IF($L$2-T$1=$L$1-$M11, $L$3^($L$1-$M11), ($L$3*T12*U12/(T12+($L$3-1)*U12) )))) | U11: =IF(U$1>$L$2, "", IF(U$1=$L$2, 1, IF($L$2-U$1=$L$1-$M11, $L$3^($L$1-$M11), ($L$3*U12*V12/(U12+($L$3-1)*V12) )))) | ... DJ11: =IF(DJ$1>$L$2, "", IF(DJ$1=$L$2, 1, IF($L$2-DJ$1=$L$1-$M11, $L$3^($L$1-$M11), ($L$3*DJ12*DK12/(DJ12+($L$3-1)*DK12) ))))
A12: =MASANIELLO!C14 -> W | B12: =IF( OR(I11=$L$2,H11=1+$L$1-$L$2), "", IF(A12="l",0,IF(A12="w",1,"")) ) -> 1 | C12: =IF(OR(I11>=$L$2,D11=""),"",IF(ISERROR((1-$L$3*INDEX($N$2:$DJ$101,H11+I11+2,I11+2)/(INDEX($N$2:$DJ$101,H11+I11+2,I11+1)+($L$3-1)*(INDEX($N$2:$DJ$101,H11+I11+2,I11+2))))*$F11), $F11, (1-$L$3*INDEX($N$2:$DJ$101,H11+I11+2,I11+2)/(INDEX($N$2:$DJ$101,H11+I11+2,I11+1)+($L$3-1)*(INDEX($N$2:$DJ$101,H11+I11+2,I11+2))))*$F11 ) ) -> 9.9670292 | D12: =IF(I11>=$L$2,"",IF(B12="", "", C12*($L$3-1)*B12) ) -> 12.957138 | E12: =IF(B12="","",( D12-(IF((D12+F11)<=G11, D12, (G11-F11) )) )*(100-$L$5)/100 ) -> 0 | F12: =IF(I11>=$L$2,"",IF(B12="", "", IF(B12=0, F11-C12, IF( ((F11+D12)-G11)>=0, F11+(G11-F11)+((D12-(G11-F11))*$L$5/100), F11+D12 ) )) ) -> 84.314263 | G12: =IF(F12>G11, F12, G11) -> 84.314263 | H12: =IF( $L$4=0, IF(I11+B12=$L$2,0,IF(B12=0,H11+1,H11)), IF( F12>=G11, 0, IF(B12=0,H11+1,H11) ) ) -> 0 | I12: =IF( $L$4=0, IF(I11+B12=$L$2,0,IF(B12=1,I11+1,I11)), IF( F12>=G11, 0, IF(B12=1,I11+1,I11) ) ) -> 1 | J12: =IF( B12="", "", IF( ISERROR((B12+I11)/(H11+I11+1)), 0, (B12+I11)/(H11+I11+1) ) ) -> 1 | M12: =IF(M11<($L$1-1),M11+1) -> FALSE | N12: =IF(N$1>$L$2, "", IF(N$1=$L$2, 1, IF($L$2-N$1=$L$1-$M12, $L$3^($L$1-$M12), ($L$3*N13*O13/(N13+($L$3-1)*O13) )))) -> #DIV/0! | O12: =IF(O$1>$L$2, "", IF(O$1=$L$2, 1, IF($L$2-O$1=$L$1-$M12, $L$3^($L$1-$M12), ($L$3*O13*P13/(O13+($L$3-1)*P13) )))) -> #DIV/0! | P12: =IF(P$1>$L$2, "", IF(P$1=$L$2, 1, IF($L$2-P$1=$L$1-$M12, $L$3^($L$1-$M12), ($L$3*P13*Q13/(P13+($L$3-1)*Q13) )))) -> #DIV/0! | Q12: =IF(Q$1>$L$2, "", IF(Q$1=$L$2, 1, IF($L$2-Q$1=$L$1-$M12, $L$3^($L$1-$M12), ($L$3*Q13*R13/(Q13+($L$3-1)*R13) )))) -> #DIV/0! | R12: =IF(R$1>$L$2, "", IF(R$1=$L$2, 1, IF($L$2-R$1=$L$1-$M12, $L$3^($L$1-$M12), ($L$3*R13*S13/(R13+($L$3-1)*S13) )))) -> 1 | S12: =IF(S$1>$L$2, "", IF(S$1=$L$2, 1, IF($L$2-S$1=$L$1-$M12, $L$3^($L$1-$M12), ($L$3*S13*T13/(S13+($L$3-1)*T13) )))) | T12: =IF(T$1>$L$2, "", IF(T$1=$L$2, 1, IF($L$2-T$1=$L$1-$M12, $L$3^($L$1-$M12), ($L$3*T13*U13/(T13+($L$3-1)*U13) )))) | U12: =IF(U$1>$L$2, "", IF(U$1=$L$2, 1, IF($L$2-U$1=$L$1-$M12, $L$3^($L$1-$M12), ($L$3*U13*V13/(U13+($L$3-1)*V13) )))) | ... DJ12: =IF(DJ$1>$L$2, "", IF(DJ$1=$L$2, 1, IF($L$2-DJ$1=$L$1-$M12, $L$3^($L$1-$M12), ($L$3*DJ13*DK13/(DJ13+($L$3-1)*DK13) ))))
A13: =MASANIELLO!C15 -> W | B13: =IF( OR(I12=$L$2,H12=1+$L$1-$L$2), "", IF(A13="l",0,IF(A13="w",1,"")) ) -> 1 | C13: =IF(OR(I12>=$L$2,D12=""),"",IF(ISERROR((1-$L$3*INDEX($N$2:$DJ$101,H12+I12+2,I12+2)/(INDEX($N$2:$DJ$101,H12+I12+2,I12+1)+($L$3-1)*(INDEX($N$2:$DJ$101,H12+I12+2,I12+2))))*$F12), $F12, (1-$L$3*INDEX($N$2:$DJ$101,H12+I12+2,I12+2)/(INDEX($N$2:$DJ$101,H12+I12+2,I12+1)+($L$3-1)*(INDEX($N$2:$DJ$101,H12+I12+2,I12+2))))*$F12 ) ) -> 7.641389 | D13: =IF(I12>=$L$2,"",IF(B13="", "", C13*($L$3-1)*B13) ) -> 9.9338057 | E13: =IF(B13="","",( D13-(IF((D13+F12)<=G12, D13, (G12-F12) )) )*(100-$L$5)/100 ) -> 0 | F13: =IF(I12>=$L$2,"",IF(B13="", "", IF(B13=0, F12-C13, IF( ((F12+D13)-G12)>=0, F12+(G12-F12)+((D13-(G12-F12))*$L$5/100), F12+D13 ) )) ) -> 94.248069 | G13: =IF(F13>G12, F13, G12) -> 94.248069 | H13: =IF( $L$4=0, IF(I12+B13=$L$2,0,IF(B13=0,H12+1,H12)), IF( F13>=G12, 0, IF(B13=0,H12+1,H12) ) ) -> 0 | I13: =IF( $L$4=0, IF(I12+B13=$L$2,0,IF(B13=1,I12+1,I12)), IF( F13>=G12, 0, IF(B13=1,I12+1,I12) ) ) -> 2 | J13: =IF( B13="", "", IF( ISERROR((B13+I12)/(H12+I12+1)), 0, (B13+I12)/(H12+I12+1) ) ) -> 1 | M13: =IF(M12<($L$1-1),M12+1) -> FALSE | N13: =IF(N$1>$L$2, "", IF(N$1=$L$2, 1, IF($L$2-N$1=$L$1-$M13, $L$3^($L$1-$M13), ($L$3*N14*O14/(N14+($L$3-1)*O14) )))) -> #DIV/0! | O13: =IF(O$1>$L$2, "", IF(O$1=$L$2, 1, IF($L$2-O$1=$L$1-$M13, $L$3^($L$1-$M13), ($L$3*O14*P14/(O14+($L$3-1)*P14) )))) -> #DIV/0! | P13: =IF(P$1>$L$2, "", IF(P$1=$L$2, 1, IF($L$2-P$1=$L$1-$M13, $L$3^($L$1-$M13), ($L$3*P14*Q14/(P14+($L$3-1)*Q14) )))) -> #DIV/0! | Q13: =IF(Q$1>$L$2, "", IF(Q$1=$L$2, 1, IF($L$2-Q$1=$L$1-$M13, $L$3^($L$1-$M13), ($L$3*Q14*R14/(Q14+($L$3-1)*R14) )))) -> #DIV/0! | R13: =IF(R$1>$L$2, "", IF(R$1=$L$2, 1, IF($L$2-R$1=$L$1-$M13, $L$3^($L$1-$M13), ($L$3*R14*S14/(R14+($L$3-1)*S14) )))) -> 1 | S13: =IF(S$1>$L$2, "", IF(S$1=$L$2, 1, IF($L$2-S$1=$L$1-$M13, $L$3^($L$1-$M13), ($L$3*S14*T14/(S14+($L$3-1)*T14) )))) | T13: =IF(T$1>$L$2, "", IF(T$1=$L$2, 1, IF($L$2-T$1=$L$1-$M13, $L$3^($L$1-$M13), ($L$3*T14*U14/(T14+($L$3-1)*U14) )))) | U13: =IF(U$1>$L$2, "", IF(U$1=$L$2, 1, IF($L$2-U$1=$L$1-$M13, $L$3^($L$1-$M13), ($L$3*U14*V14/(U14+($L$3-1)*V14) )))) | ... DJ13: =IF(DJ$1>$L$2, "", IF(DJ$1=$L$2, 1, IF($L$2-DJ$1=$L$1-$M13, $L$3^($L$1-$M13), ($L$3*DJ14*DK14/(DJ14+($L$3-1)*DK14) ))))
A14: =MASANIELLO!C16 -> W | B14: =IF( OR(I13=$L$2,H13=1+$L$1-$L$2), "", IF(A14="l",0,IF(A14="w",1,"")) ) -> 1 | C14: =IF(OR(I13>=$L$2,D13=""),"",IF(ISERROR((1-$L$3*INDEX($N$2:$DJ$101,H13+I13+2,I13+2)/(INDEX($N$2:$DJ$101,H13+I13+2,I13+1)+($L$3-1)*(INDEX($N$2:$DJ$101,H13+I13+2,I13+2))))*$F13), $F13, (1-$L$3*INDEX($N$2:$DJ$101,H13+I13+2,I13+2)/(INDEX($N$2:$DJ$101,H13+I13+2,I13+1)+($L$3-1)*(INDEX($N$2:$DJ$101,H13+I13+2,I13+2))))*$F13 ) ) -> 4.3937987 | D14: =IF(I13>=$L$2,"",IF(B14="", "", C14*($L$3-1)*B14) ) -> 5.7119383 | E14: =IF(B14="","",( D14-(IF((D14+F13)<=G13, D14, (G13-F13) )) )*(100-$L$5)/100 ) -> 0 | F14: =IF(I13>=$L$2,"",IF(B14="", "", IF(B14=0, F13-C14, IF( ((F13+D14)-G13)>=0, F13+(G13-F13)+((D14-(G13-F13))*$L$5/100), F13+D14 ) )) ) -> 99.960007 | G14: =IF(F14>G13, F14, G13) -> 99.960007 | H14: =IF( $L$4=0, IF(I13+B14=$L$2,0,IF(B14=0,H13+1,H13)), IF( F14>=G13, 0, IF(B14=0,H13+1,H13) ) ) -> 0 | I14: =IF( $L$4=0, IF(I13+B14=$L$2,0,IF(B14=1,I13+1,I13)), IF( F14>=G13, 0, IF(B14=1,I13+1,I13) ) ) -> 3 | J14: =IF( B14="", "", IF( ISERROR((B14+I13)/(H13+I13+1)), 0, (B14+I13)/(H13+I13+1) ) ) -> 1 | M14: =IF(M13<($L$1-1),M13+1) -> FALSE | N14: =IF(N$1>$L$2, "", IF(N$1=$L$2, 1, IF($L$2-N$1=$L$1-$M14, $L$3^($L$1-$M14), ($L$3*N15*O15/(N15+($L$3-1)*O15) )))) -> #DIV/0! | O14: =IF(O$1>$L$2, "", IF(O$1=$L$2, 1, IF($L$2-O$1=$L$1-$M14, $L$3^($L$1-$M14), ($L$3*O15*P15/(O15+($L$3-1)*P15) )))) -> #DIV/0! | P14: =IF(P$1>$L$2, "", IF(P$1=$L$2, 1, IF($L$2-P$1=$L$1-$M14, $L$3^($L$1-$M14), ($L$3*P15*Q15/(P15+($L$3-1)*Q15) )))) -> #DIV/0! | Q14: =IF(Q$1>$L$2, "", IF(Q$1=$L$2, 1, IF($L$2-Q$1=$L$1-$M14, $L$3^($L$1-$M14), ($L$3*Q15*R15/(Q15+($L$3-1)*R15) )))) -> #DIV/0! | R14: =IF(R$1>$L$2, "", IF(R$1=$L$2, 1, IF($L$2-R$1=$L$1-$M14, $L$3^($L$1-$M14), ($L$3*R15*S15/(R15+($L$3-1)*S15) )))) -> 1 | S14: =IF(S$1>$L$2, "", IF(S$1=$L$2, 1, IF($L$2-S$1=$L$1-$M14, $L$3^($L$1-$M14), ($L$3*S15*T15/(S15+($L$3-1)*T15) )))) | T14: =IF(T$1>$L$2, "", IF(T$1=$L$2, 1, IF($L$2-T$1=$L$1-$M14, $L$3^($L$1-$M14), ($L$3*T15*U15/(T15+($L$3-1)*U15) )))) | U14: =IF(U$1>$L$2, "", IF(U$1=$L$2, 1, IF($L$2-U$1=$L$1-$M14, $L$3^($L$1-$M14), ($L$3*U15*V15/(U15+($L$3-1)*V15) )))) | ... DJ14: =IF(DJ$1>$L$2, "", IF(DJ$1=$L$2, 1, IF($L$2-DJ$1=$L$1-$M14, $L$3^($L$1-$M14), ($L$3*DJ15*DK15/(DJ15+($L$3-1)*DK15) ))))
A15: =MASANIELLO!C17 -> W | B15: =IF( OR(I14=$L$2,H14=1+$L$1-$L$2), "", IF(A15="l",0,IF(A15="w",1,"")) ) -> 1 | C15: =IF(OR(I14>=$L$2,D14=""),"",IF(ISERROR((1-$L$3*INDEX($N$2:$DJ$101,H14+I14+2,I14+2)/(INDEX($N$2:$DJ$101,H14+I14+2,I14+1)+($L$3-1)*(INDEX($N$2:$DJ$101,H14+I14+2,I14+2))))*$F14), $F14, (1-$L$3*INDEX($N$2:$DJ$101,H14+I14+2,I14+2)/(INDEX($N$2:$DJ$101,H14+I14+2,I14+1)+($L$3-1)*(INDEX($N$2:$DJ$101,H14+I14+2,I14+2))))*$F14 ) ) -> 1.4436767 | D15: =IF(I14>=$L$2,"",IF(B15="", "", C15*($L$3-1)*B15) ) -> 1.8767797 | E15: =IF(B15="","",( D15-(IF((D15+F14)<=G14, D15, (G14-F14) )) )*(100-$L$5)/100 ) -> 0 | F15: =IF(I14>=$L$2,"",IF(B15="", "", IF(B15=0, F14-C15, IF( ((F14+D15)-G14)>=0, F14+(G14-F14)+((D15-(G14-F14))*$L$5/100), F14+D15 ) )) ) -> 101.83679 | G15: =IF(F15>G14, F15, G14) -> 101.83679 | H15: =IF( $L$4=0, IF(I14+B15=$L$2,0,IF(B15=0,H14+1,H14)), IF( F15>=G14, 0, IF(B15=0,H14+1,H14) ) ) -> 0 | I15: =IF( $L$4=0, IF(I14+B15=$L$2,0,IF(B15=1,I14+1,I14)), IF( F15>=G14, 0, IF(B15=1,I14+1,I14) ) ) -> 0 | J15: =IF( B15="", "", IF( ISERROR((B15+I14)/(H14+I14+1)), 0, (B15+I14)/(H14+I14+1) ) ) -> 1 | M15: =IF(M14<($L$1-1),M14+1) -> FALSE | N15: =IF(N$1>$L$2, "", IF(N$1=$L$2, 1, IF($L$2-N$1=$L$1-$M15, $L$3^($L$1-$M15), ($L$3*N16*O16/(N16+($L$3-1)*O16) )))) -> #DIV/0! | O15: =IF(O$1>$L$2, "", IF(O$1=$L$2, 1, IF($L$2-O$1=$L$1-$M15, $L$3^($L$1-$M15), ($L$3*O16*P16/(O16+($L$3-1)*P16) )))) -> #DIV/0! | P15: =IF(P$1>$L$2, "", IF(P$1=$L$2, 1, IF($L$2-P$1=$L$1-$M15, $L$3^($L$1-$M15), ($L$3*P16*Q16/(P16+($L$3-1)*Q16) )))) -> #DIV/0! | Q15: =IF(Q$1>$L$2, "", IF(Q$1=$L$2, 1, IF($L$2-Q$1=$L$1-$M15, $L$3^($L$1-$M15), ($L$3*Q16*R16/(Q16+($L$3-1)*R16) )))) -> #DIV/0! | R15: =IF(R$1>$L$2, "", IF(R$1=$L$2, 1, IF($L$2-R$1=$L$1-$M15, $L$3^($L$1-$M15), ($L$3*R16*S16/(R16+($L$3-1)*S16) )))) -> 1 | S15: =IF(S$1>$L$2, "", IF(S$1=$L$2, 1, IF($L$2-S$1=$L$1-$M15, $L$3^($L$1-$M15), ($L$3*S16*T16/(S16+($L$3-1)*T16) )))) | T15: =IF(T$1>$L$2, "", IF(T$1=$L$2, 1, IF($L$2-T$1=$L$1-$M15, $L$3^($L$1-$M15), ($L$3*T16*U16/(T16+($L$3-1)*U16) )))) | U15: =IF(U$1>$L$2, "", IF(U$1=$L$2, 1, IF($L$2-U$1=$L$1-$M15, $L$3^($L$1-$M15), ($L$3*U16*V16/(U16+($L$3-1)*V16) )))) | ... DJ15: =IF(DJ$1>$L$2, "", IF(DJ$1=$L$2, 1, IF($L$2-DJ$1=$L$1-$M15, $L$3^($L$1-$M15), ($L$3*DJ16*DK16/(DJ16+($L$3-1)*DK16) ))))
A16: =MASANIELLO!C18 -> W | B16: =IF( OR(I15=$L$2,H15=1+$L$1-$L$2), "", IF(A16="l",0,IF(A16="w",1,"")) ) -> 1 | C16: =IF(OR(I15>=$L$2,D15=""),"",IF(ISERROR((1-$L$3*INDEX($N$2:$DJ$101,H15+I15+2,I15+2)/(INDEX($N$2:$DJ$101,H15+I15+2,I15+1)+($L$3-1)*(INDEX($N$2:$DJ$101,H15+I15+2,I15+2))))*$F15), $F15, (1-$L$3*INDEX($N$2:$DJ$101,H15+I15+2,I15+2)/(INDEX($N$2:$DJ$101,H15+I15+2,I15+1)+($L$3-1)*(INDEX($N$2:$DJ$101,H15+I15+2,I15+2))))*$F15 ) ) -> 14.224371 | D16: =IF(I15>=$L$2,"",IF(B16="", "", C16*($L$3-1)*B16) ) -> 18.491682 | E16: =IF(B16="","",( D16-(IF((D16+F15)<=G15, D16, (G15-F15) )) )*(100-$L$5)/100 ) -> 0 | F16: =IF(I15>=$L$2,"",IF(B16="", "", IF(B16=0, F15-C16, IF( ((F15+D16)-G15)>=0, F15+(G15-F15)+((D16-(G15-F15))*$L$5/100), F15+D16 ) )) ) -> 120.32847 | G16: =IF(F16>G15, F16, G15) -> 120.32847 | H16: =IF( $L$4=0, IF(I15+B16=$L$2,0,IF(B16=0,H15+1,H15)), IF( F16>=G15, 0, IF(B16=0,H15+1,H15) ) ) -> 0 | I16: =IF( $L$4=0, IF(I15+B16=$L$2,0,IF(B16=1,I15+1,I15)), IF( F16>=G15, 0, IF(B16=1,I15+1,I15) ) ) -> 1 | J16: =IF( B16="", "", IF( ISERROR((B16+I15)/(H15+I15+1)), 0, (B16+I15)/(H15+I15+1) ) ) -> 1 | M16: =IF(M15<($L$1-1),M15+1) -> FALSE | N16: =IF(N$1>$L$2, "", IF(N$1=$L$2, 1, IF($L$2-N$1=$L$1-$M16, $L$3^($L$1-$M16), ($L$3*N17*O17/(N17+($L$3-1)*O17) )))) -> #DIV/0! | O16: =IF(O$1>$L$2, "", IF(O$1=$L$2, 1, IF($L$2-O$1=$L$1-$M16, $L$3^($L$1-$M16), ($L$3*O17*P17/(O17+($L$3-1)*P17) )))) -> #DIV/0! | P16: =IF(P$1>$L$2, "", IF(P$1=$L$2, 1, IF($L$2-P$1=$L$1-$M16, $L$3^($L$1-$M16), ($L$3*P17*Q17/(P17+($L$3-1)*Q17) )))) -> #DIV/0! | Q16: =IF(Q$1>$L$2, "", IF(Q$1=$L$2, 1, IF($L$2-Q$1=$L$1-$M16, $L$3^($L$1-$M16), ($L$3*Q17*R17/(Q17+($L$3-1)*R17) )))) -> #DIV/0! | R16: =IF(R$1>$L$2, "", IF(R$1=$L$2, 1, IF($L$2-R$1=$L$1-$M16, $L$3^($L$1-$M16), ($L$3*R17*S17/(R17+($L$3-1)*S17) )))) -> 1 | S16: =IF(S$1>$L$2, "", IF(S$1=$L$2, 1, IF($L$2-S$1=$L$1-$M16, $L$3^($L$1-$M16), ($L$3*S17*T17/(S17+($L$3-1)*T17) )))) | T16: =IF(T$1>$L$2, "", IF(T$1=$L$2, 1, IF($L$2-T$1=$L$1-$M16, $L$3^($L$1-$M16), ($L$3*T17*U17/(T17+($L$3-1)*U17) )))) | U16: =IF(U$1>$L$2, "", IF(U$1=$L$2, 1, IF($L$2-U$1=$L$1-$M16, $L$3^($L$1-$M16), ($L$3*U17*V17/(U17+($L$3-1)*V17) )))) | ... DJ16: =IF(DJ$1>$L$2, "", IF(DJ$1=$L$2, 1, IF($L$2-DJ$1=$L$1-$M16, $L$3^($L$1-$M16), ($L$3*DJ17*DK17/(DJ17+($L$3-1)*DK17) ))))
A17: =MASANIELLO!C19 -> W | B17: =IF( OR(I16=$L$2,H16=1+$L$1-$L$2), "", IF(A17="l",0,IF(A17="w",1,"")) ) -> 1 | C17: =IF(OR(I16>=$L$2,D16=""),"",IF(ISERROR((1-$L$3*INDEX($N$2:$DJ$101,H16+I16+2,I16+2)/(INDEX($N$2:$DJ$101,H16+I16+2,I16+1)+($L$3-1)*(INDEX($N$2:$DJ$101,H16+I16+2,I16+2))))*$F16), $F16, (1-$L$3*INDEX($N$2:$DJ$101,H16+I16+2,I16+2)/(INDEX($N$2:$DJ$101,H16+I16+2,I16+1)+($L$3-1)*(INDEX($N$2:$DJ$101,H16+I16+2,I16+2))))*$F16 ) ) -> 10.905351 | D17: =IF(I16>=$L$2,"",IF(B17="", "", C17*($L$3-1)*B17) ) -> 14.176956 | E17: =IF(B17="","",( D17-(IF((D17+F16)<=G16, D17, (G16-F16) )) )*(100-$L$5)/100 ) -> 0 | F17: =IF(I16>=$L$2,"",IF(B17="", "", IF(B17=0, F16-C17, IF( ((F16+D17)-G16)>=0, F16+(G16-F16)+((D17-(G16-F16))*$L$5/100), F16+D17 ) )) ) -> 134.50543 | G17: =IF(F17>G16, F17, G16) -> 134.50543 | H17: =IF( $L$4=0, IF(I16+B17=$L$2,0,IF(B17=0,H16+1,H16)), IF( F17>=G16, 0, IF(B17=0,H16+1,H16) ) ) -> 0 | I17: =IF( $L$4=0, IF(I16+B17=$L$2,0,IF(B17=1,I16+1,I16)), IF( F17>=G16, 0, IF(B17=1,I16+1,I16) ) ) -> 2 | J17: =IF( B17="", "", IF( ISERROR((B17+I16)/(H16+I16+1)), 0, (B17+I16)/(H16+I16+1) ) ) -> 1 | M17: =IF(M16<($L$1-1),M16+1) -> FALSE | N17: =IF(N$1>$L$2, "", IF(N$1=$L$2, 1, IF($L$2-N$1=$L$1-$M17, $L$3^($L$1-$M17), ($L$3*N18*O18/(N18+($L$3-1)*O18) )))) -> #DIV/0! | O17: =IF(O$1>$L$2, "", IF(O$1=$L$2, 1, IF($L$2-O$1=$L$1-$M17, $L$3^($L$1-$M17), ($L$3*O18*P18/(O18+($L$3-1)*P18) )))) -> #DIV/0! | P17: =IF(P$1>$L$2, "", IF(P$1=$L$2, 1, IF($L$2-P$1=$L$1-$M17, $L$3^($L$1-$M17), ($L$3*P18*Q18/(P18+($L$3-1)*Q18) )))) -> #DIV/0! | Q17: =IF(Q$1>$L$2, "", IF(Q$1=$L$2, 1, IF($L$2-Q$1=$L$1-$M17, $L$3^($L$1-$M17), ($L$3*Q18*R18/(Q18+($L$3-1)*R18) )))) -> #DIV/0! | R17: =IF(R$1>$L$2, "", IF(R$1=$L$2, 1, IF($L$2-R$1=$L$1-$M17, $L$3^($L$1-$M17), ($L$3*R18*S18/(R18+($L$3-1)*S18) )))) -> 1 | S17: =IF(S$1>$L$2, "", IF(S$1=$L$2, 1, IF($L$2-S$1=$L$1-$M17, $L$3^($L$1-$M17), ($L$3*S18*T18/(S18+($L$3-1)*T18) )))) | T17: =IF(T$1>$L$2, "", IF(T$1=$L$2, 1, IF($L$2-T$1=$L$1-$M17, $L$3^($L$1-$M17), ($L$3*T18*U18/(T18+($L$3-1)*U18) )))) | U17: =IF(U$1>$L$2, "", IF(U$1=$L$2, 1, IF($L$2-U$1=$L$1-$M17, $L$3^($L$1-$M17), ($L$3*U18*V18/(U18+($L$3-1)*V18) )))) | ... DJ17: =IF(DJ$1>$L$2, "", IF(DJ$1=$L$2, 1, IF($L$2-DJ$1=$L$1-$M17, $L$3^($L$1-$M17), ($L$3*DJ18*DK18/(DJ18+($L$3-1)*DK18) ))))
... A21: =MASANIELLO!C23 -> 0 | B21: =IF( OR(I20=$L$2,H20=1+$L$1-$L$2), "", IF(A21="l",0,IF(A21="w",1,"")) ) -> #VALUE! | C21: =IF(OR(I20>=$L$2,D20=""),"",IF(ISERROR((1-$L$3*INDEX($N$2:$DJ$101,H20+I20+2,I20+2)/(INDEX($N$2:$DJ$101,H20+I20+2,I20+1)+($L$3-1)*(INDEX($N$2:$DJ$101,H20+I20+2,I20+2))))*$F20), $F20, (1-$L$3*INDEX($N$2:$DJ$101,H20+I20+2,I20+2)/(INDEX($N$2:$DJ$101,H20+I20+2,I20+1)+($L$3-1)*(INDEX($N$2:$DJ$101,H20+I20+2,I20+2))))*$F20 ) ) -> #VALUE! | D21: =IF(I20>=$L$2,"",IF(B21="", "", C21*($L$3-1)*B21) ) -> #VALUE! | E21: =IF(B21="","",( D21-(IF((D21+F20)<=G20, D21, (G20-F20) )) )*(100-$L$5)/100 ) -> #VALUE! | F21: =IF(I20>=$L$2,"",IF(B21="", "", IF(B21=0, F20-C21, IF( ((F20+D21)-G20)>=0, F20+(G20-F20)+((D21-(G20-F20))*$L$5/100), F20+D21 ) )) ) -> #VALUE! | G21: =IF(F21>G20, F21, G20) -> #VALUE! | H21: =IF( $L$4=0, IF(I20+B21=$L$2,0,IF(B21=0,H20+1,H20)), IF( F21>=G20, 0, IF(B21=0,H20+1,H20) ) ) -> #VALUE! | I21: =IF( $L$4=0, IF(I20+B21=$L$2,0,IF(B21=1,I20+1,I20)), IF( F21>=G20, 0, IF(B21=1,I20+1,I20) ) ) -> #VALUE! | J21: =IF( B21="", "", IF( ISERROR((B21+I20)/(H20+I20+1)), 0, (B21+I20)/(H20+I20+1) ) ) -> #VALUE! | M21: =IF(M20<($L$1-1),M20+1) -> FALSE | N21: =IF(N$1>$L$2, "", IF(N$1=$L$2, 1, IF($L$2-N$1=$L$1-$M21, $L$3^($L$1-$M21), ($L$3*N22*O22/(N22+($L$3-1)*O22) )))) -> #DIV/0! | O21: =IF(O$1>$L$2, "", IF(O$1=$L$2, 1, IF($L$2-O$1=$L$1-$M21, $L$3^($L$1-$M21), ($L$3*O22*P22/(O22+($L$3-1)*P22) )))) -> #DIV/0! | P21: =IF(P$1>$L$2, "", IF(P$1=$L$2, 1, IF($L$2-P$1=$L$1-$M21, $L$3^($L$1-$M21), ($L$3*P22*Q22/(P22+($L$3-1)*Q22) )))) -> #DIV/0! | Q21: =IF(Q$1>$L$2, "", IF(Q$1=$L$2, 1, IF($L$2-Q$1=$L$1-$M21, $L$3^($L$1-$M21), ($L$3*Q22*R22/(Q22+($L$3-1)*R22) )))) -> #DIV/0! | R21: =IF(R$1>$L$2, "", IF(R$1=$L$2, 1, IF($L$2-R$1=$L$1-$M21, $L$3^($L$1-$M21), ($L$3*R22*S22/(R22+($L$3-1)*S22) )))) -> 1 | S21: =IF(S$1>$L$2, "", IF(S$1=$L$2, 1, IF($L$2-S$1=$L$1-$M21, $L$3^($L$1-$M21), ($L$3*S22*T22/(S22+($L$3-1)*T22) )))) | T21: =IF(T$1>$L$2, "", IF(T$1=$L$2, 1, IF($L$2-T$1=$L$1-$M21, $L$3^($L$1-$M21), ($L$3*T22*U22/(T22+($L$3-1)*U22) )))) | U21: =IF(U$1>$L$2, "", IF(U$1=$L$2, 1, IF($L$2-U$1=$L$1-$M21, $L$3^($L$1-$M21), ($L$3*U22*V22/(U22+($L$3-1)*V22) )))) | ... DJ21: =IF(DJ$1>$L$2, "", IF(DJ$1=$L$2, 1, IF($L$2-DJ$1=$L$1-$M21, $L$3^($L$1-$M21), ($L$3*DJ22*DK22/(DJ22+($L$3-1)*DK22) ))))
A22: =MASANIELLO!#REF! -> #REF! | B22: =IF( OR(I21=$L$2,H21=1+$L$1-$L$2), "", IF(A22="l",0,IF(A22="w",1,"")) ) -> #VALUE! | C22: =IF(OR(I21>=$L$2,D21=""),"",IF(ISERROR((1-$L$3*INDEX($N$2:$DJ$101,H21+I21+2,I21+2)/(INDEX($N$2:$DJ$101,H21+I21+2,I21+1)+($L$3-1)*(INDEX($N$2:$DJ$101,H21+I21+2,I21+2))))*$F21), $F21, (1-$L$3*INDEX($N$2:$DJ$101,H21+I21+2,I21+2)/(INDEX($N$2:$DJ$101,H21+I21+2,I21+1)+($L$3-1)*(INDEX($N$2:$DJ$101,H21+I21+2,I21+2))))*$F21 ) ) -> #VALUE! | D22: =IF(I21>=$L$2,"",IF(B22="", "", C22*($L$3-1)*B22) ) -> #VALUE! | E22: =IF(B22="","",( D22-(IF((D22+F21)<=G21, D22, (G21-F21) )) )*(100-$L$5)/100 ) -> #VALUE! | F22: =IF(I21>=$L$2,"",IF(B22="", "", IF(B22=0, F21-C22, IF( ((F21+D22)-G21)>=0, F21+(G21-F21)+((D22-(G21-F21))*$L$5/100), F21+D22 ) )) ) -> #VALUE! | G22: =IF(F22>G21, F22, G21) -> #VALUE! | H22: =IF( $L$4=0, IF(I21+B22=$L$2,0,IF(B22=0,H21+1,H21)), IF( F22>=G21, 0, IF(B22=0,H21+1,H21) ) ) -> #VALUE! | I22: =IF( $L$4=0, IF(I21+B22=$L$2,0,IF(B22=1,I21+1,I21)), IF( F22>=G21, 0, IF(B22=1,I21+1,I21) ) ) -> #VALUE! | J22: =IF( B22="", "", IF( ISERROR((B22+I21)/(H21+I21+1)), 0, (B22+I21)/(H21+I21+1) ) ) -> #VALUE! | M22: =IF(M21<($L$1-1),M21+1) -> FALSE | N22: =IF(N$1>$L$2, "", IF(N$1=$L$2, 1, IF($L$2-N$1=$L$1-$M22, $L$3^($L$1-$M22), ($L$3*N23*O23/(N23+($L$3-1)*O23) )))) -> #DIV/0! | O22: =IF(O$1>$L$2, "", IF(O$1=$L$2, 1, IF($L$2-O$1=$L$1-$M22, $L$3^($L$1-$M22), ($L$3*O23*P23/(O23+($L$3-1)*P23) )))) -> #DIV/0! | P22: =IF(P$1>$L$2, "", IF(P$1=$L$2, 1, IF($L$2-P$1=$L$1-$M22, $L$3^($L$1-$M22), ($L$3*P23*Q23/(P23+($L$3-1)*Q23) )))) -> #DIV/0! | Q22: =IF(Q$1>$L$2, "", IF(Q$1=$L$2, 1, IF($L$2-Q$1=$L$1-$M22, $L$3^($L$1-$M22), ($L$3*Q23*R23/(Q23+($L$3-1)*R23) )))) -> #DIV/0! | R22: =IF(R$1>$L$2, "", IF(R$1=$L$2, 1, IF($L$2-R$1=$L$1-$M22, $L$3^($L$1-$M22), ($L$3*R23*S23/(R23+($L$3-1)*S23) )))) -> 1 | S22: =IF(S$1>$L$2, "", IF(S$1=$L$2, 1, IF($L$2-S$1=$L$1-$M22, $L$3^($L$1-$M22), ($L$3*S23*T23/(S23+($L$3-1)*T23) )))) | T22: =IF(T$1>$L$2, "", IF(T$1=$L$2, 1, IF($L$2-T$1=$L$1-$M22, $L$3^($L$1-$M22), ($L$3*T23*U23/(T23+($L$3-1)*U23) )))) | U22: =IF(U$1>$L$2, "", IF(U$1=$L$2, 1, IF($L$2-U$1=$L$1-$M22, $L$3^($L$1-$M22), ($L$3*U23*V23/(U23+($L$3-1)*V23) )))) | ... DJ22: =IF(DJ$1>$L$2, "", IF(DJ$1=$L$2, 1, IF($L$2-DJ$1=$L$1-$M22, $L$3^($L$1-$M22), ($L$3*DJ23*DK23/(DJ23+($L$3-1)*DK23) ))))
A23: =MASANIELLO!#REF! -> #REF! | B23: =IF( OR(I22=$L$2,H22=1+$L$1-$L$2), "", IF(A23="l",0,IF(A23="w",1,"")) ) -> #VALUE! | C23: =IF(OR(I22>=$L$2,D22=""),"",IF(ISERROR((1-$L$3*INDEX($N$2:$DJ$101,H22+I22+2,I22+2)/(INDEX($N$2:$DJ$101,H22+I22+2,I22+1)+($L$3-1)*(INDEX($N$2:$DJ$101,H22+I22+2,I22+2))))*$F22), $F22, (1-$L$3*INDEX($N$2:$DJ$101,H22+I22+2,I22+2)/(INDEX($N$2:$DJ$101,H22+I22+2,I22+1)+($L$3-1)*(INDEX($N$2:$DJ$101,H22+I22+2,I22+2))))*$F22 ) ) -> #VALUE! | D23: =IF(I22>=$L$2,"",IF(B23="", "", C23*($L$3-1)*B23) ) -> #VALUE! | E23: =IF(B23="","",( D23-(IF((D23+F22)<=G22, D23, (G22-F22) )) )*(100-$L$5)/100 ) -> #VALUE! | F23: =IF(I22>=$L$2,"",IF(B23="", "", IF(B23=0, F22-C23, IF( ((F22+D23)-G22)>=0, F22+(G22-F22)+((D23-(G22-F22))*$L$5/100), F22+D23 ) )) ) -> #VALUE! | G23: =IF(F23>G22, F23, G22) -> #VALUE! | H23: =IF( $L$4=0, IF(I22+B23=$L$2,0,IF(B23=0,H22+1,H22)), IF( F23>=G22, 0, IF(B23=0,H22+1,H22) ) ) -> #VALUE! | I23: =IF( $L$4=0, IF(I22+B23=$L$2,0,IF(B23=1,I22+1,I22)), IF( F23>=G22, 0, IF(B23=1,I22+1,I22) ) ) -> #VALUE! | J23: =IF( B23="", "", IF( ISERROR((B23+I22)/(H22+I22+1)), 0, (B23+I22)/(H22+I22+1) ) ) -> #VALUE! | M23: =IF(M22<($L$1-1),M22+1) -> FALSE | N23: =IF(N$1>$L$2, "", IF(N$1=$L$2, 1, IF($L$2-N$1=$L$1-$M23, $L$3^($L$1-$M23), ($L$3*N24*O24/(N24+($L$3-1)*O24) )))) -> #DIV/0! | O23: =IF(O$1>$L$2, "", IF(O$1=$L$2, 1, IF($L$2-O$1=$L$1-$M23, $L$3^($L$1-$M23), ($L$3*O24*P24/(O24+($L$3-1)*P24) )))) -> #DIV/0! | P23: =IF(P$1>$L$2, "", IF(P$1=$L$2, 1, IF($L$2-P$1=$L$1-$M23, $L$3^($L$1-$M23), ($L$3*P24*Q24/(P24+($L$3-1)*Q24) )))) -> #DIV/0! | Q23: =IF(Q$1>$L$2, "", IF(Q$1=$L$2, 1, IF($L$2-Q$1=$L$1-$M23, $L$3^($L$1-$M23), ($L$3*Q24*R24/(Q24+($L$3-1)*R24) )))) -> #DIV/0! | R23: =IF(R$1>$L$2, "", IF(R$1=$L$2, 1, IF($L$2-R$1=$L$1-$M23, $L$3^($L$1-$M23), ($L$3*R24*S24/(R24+($L$3-1)*S24) )))) -> 1 | S23: =IF(S$1>$L$2, "", IF(S$1=$L$2, 1, IF($L$2-S$1=$L$1-$M23, $L$3^($L$1-$M23), ($L$3*S24*T24/(S24+($L$3-1)*T24) )))) | T23: =IF(T$1>$L$2, "", IF(T$1=$L$2, 1, IF($L$2-T$1=$L$1-$M23, $L$3^($L$1-$M23), ($L$3*T24*U24/(T24+($L$3-1)*U24) )))) | U23: =IF(U$1>$L$2, "", IF(U$1=$L$2, 1, IF($L$2-U$1=$L$1-$M23, $L$3^($L$1-$M23), ($L$3*U24*V24/(U24+($L$3-1)*V24) )))) | ... DJ23: =IF(DJ$1>$L$2, "", IF(DJ$1=$L$2, 1, IF($L$2-DJ$1=$L$1-$M23, $L$3^($L$1-$M23), ($L$3*DJ24*DK24/(DJ24+($L$3-1)*DK24) ))))
A24: =MASANIELLO!#REF! -> #REF! | B24: =IF( OR(I23=$L$2,H23=1+$L$1-$L$2), "", IF(A24="l",0,IF(A24="w",1,"")) ) -> #VALUE! | C24: =IF(OR(I23>=$L$2,D23=""),"",IF(ISERROR((1-$L$3*INDEX($N$2:$DJ$101,H23+I23+2,I23+2)/(INDEX($N$2:$DJ$101,H23+I23+2,I23+1)+($L$3-1)*(INDEX($N$2:$DJ$101,H23+I23+2,I23+2))))*$F23), $F23, (1-$L$3*INDEX($N$2:$DJ$101,H23+I23+2,I23+2)/(INDEX($N$2:$DJ$101,H23+I23+2,I23+1)+($L$3-1)*(INDEX($N$2:$DJ$101,H23+I23+2,I23+2))))*$F23 ) ) -> #VALUE! | D24: =IF(I23>=$L$2,"",IF(B24="", "", C24*($L$3-1)*B24) ) -> #VALUE! | E24: =IF(B24="","",( D24-(IF((D24+F23)<=G23, D24, (G23-F23) )) )*(100-$L$5)/100 ) -> #VALUE! | F24: =IF(I23>=$L$2,"",IF(B24="", "", IF(B24=0, F23-C24, IF( ((F23+D24)-G23)>=0, F23+(G23-F23)+((D24-(G23-F23))*$L$5/100), F23+D24 ) )) ) -> #VALUE! | G24: =IF(F24>G23, F24, G23) -> #VALUE! | H24: =IF( $L$4=0, IF(I23+B24=$L$2,0,IF(B24=0,H23+1,H23)), IF( F24>=G23, 0, IF(B24=0,H23+1,H23) ) ) -> #VALUE! | I24: =IF( $L$4=0, IF(I23+B24=$L$2,0,IF(B24=1,I23+1,I23)), IF( F24>=G23, 0, IF(B24=1,I23+1,I23) ) ) -> #VALUE! | J24: =IF( B24="", "", IF( ISERROR((B24+I23)/(H23+I23+1)), 0, (B24+I23)/(H23+I23+1) ) ) -> #VALUE! | M24: =IF(M23<($L$1-1),M23+1) -> FALSE | N24: =IF(N$1>$L$2, "", IF(N$1=$L$2, 1, IF($L$2-N$1=$L$1-$M24, $L$3^($L$1-$M24), ($L$3*N25*O25/(N25+($L$3-1)*O25) )))) -> #DIV/0! | O24: =IF(O$1>$L$2, "", IF(O$1=$L$2, 1, IF($L$2-O$1=$L$1-$M24, $L$3^($L$1-$M24), ($L$3*O25*P25/(O25+($L$3-1)*P25) )))) -> #DIV/0! | P24: =IF(P$1>$L$2, "", IF(P$1=$L$2, 1, IF($L$2-P$1=$L$1-$M24, $L$3^($L$1-$M24), ($L$3*P25*Q25/(P25+($L$3-1)*Q25) )))) -> #DIV/0! | Q24: =IF(Q$1>$L$2, "", IF(Q$1=$L$2, 1, IF($L$2-Q$1=$L$1-$M24, $L$3^($L$1-$M24), ($L$3*Q25*R25/(Q25+($L$3-1)*R25) )))) -> #DIV/0! | R24: =IF(R$1>$L$2, "", IF(R$1=$L$2, 1, IF($L$2-R$1=$L$1-$M24, $L$3^($L$1-$M24), ($L$3*R25*S25/(R25+($L$3-1)*S25) )))) -> 1 | S24: =IF(S$1>$L$2, "", IF(S$1=$L$2, 1, IF($L$2-S$1=$L$1-$M24, $L$3^($L$1-$M24), ($L$3*S25*T25/(S25+($L$3-1)*T25) )))) | T24: =IF(T$1>$L$2, "", IF(T$1=$L$2, 1, IF($L$2-T$1=$L$1-$M24, $L$3^($L$1-$M24), ($L$3*T25*U25/(T25+($L$3-1)*U25) )))) | U24: =IF(U$1>$L$2, "", IF(U$1=$L$2, 1, IF($L$2-U$1=$L$1-$M24, $L$3^($L$1-$M24), ($L$3*U25*V25/(U25+($L$3-1)*V25) )))) | ... DJ24: =IF(DJ$1>$L$2, "", IF(DJ$1=$L$2, 1, IF($L$2-DJ$1=$L$1-$M24, $L$3^($L$1-$M24), ($L$3*DJ25*DK25/(DJ25+($L$3-1)*DK25) ))))
A25: =MASANIELLO!#REF! -> #REF! | B25: =IF( OR(I24=$L$2,H24=1+$L$1-$L$2), "", IF(A25="l",0,IF(A25="w",1,"")) ) -> #VALUE! | C25: =IF(OR(I24>=$L$2,D24=""),"",IF(ISERROR((1-$L$3*INDEX($N$2:$DJ$101,H24+I24+2,I24+2)/(INDEX($N$2:$DJ$101,H24+I24+2,I24+1)+($L$3-1)*(INDEX($N$2:$DJ$101,H24+I24+2,I24+2))))*$F24), $F24, (1-$L$3*INDEX($N$2:$DJ$101,H24+I24+2,I24+2)/(INDEX($N$2:$DJ$101,H24+I24+2,I24+1)+($L$3-1)*(INDEX($N$2:$DJ$101,H24+I24+2,I24+2))))*$F24 ) ) -> #VALUE! | D25: =IF(I24>=$L$2,"",IF(B25="", "", C25*($L$3-1)*B25) ) -> #VALUE! | E25: =IF(B25="","",( D25-(IF((D25+F24)<=G24, D25, (G24-F24) )) )*(100-$L$5)/100 ) -> #VALUE! | F25: =IF(I24>=$L$2,"",IF(B25="", "", IF(B25=0, F24-C25, IF( ((F24+D25)-G24)>=0, F24+(G24-F24)+((D25-(G24-F24))*$L$5/100), F24+D25 ) )) ) -> #VALUE! | G25: =IF(F25>G24, F25, G24) -> #VALUE! | H25: =IF( $L$4=0, IF(I24+B25=$L$2,0,IF(B25=0,H24+1,H24)), IF( F25>=G24, 0, IF(B25=0,H24+1,H24) ) ) -> #VALUE! | I25: =IF( $L$4=0, IF(I24+B25=$L$2,0,IF(B25=1,I24+1,I24)), IF( F25>=G24, 0, IF(B25=1,I24+1,I24) ) ) -> #VALUE! | J25: =IF( B25="", "", IF( ISERROR((B25+I24)/(H24+I24+1)), 0, (B25+I24)/(H24+I24+1) ) ) -> #VALUE! | M25: =IF(M24<($L$1-1),M24+1) -> FALSE | N25: =IF(N$1>$L$2, "", IF(N$1=$L$2, 1, IF($L$2-N$1=$L$1-$M25, $L$3^($L$1-$M25), ($L$3*N26*O26/(N26+($L$3-1)*O26) )))) -> #DIV/0! | O25: =IF(O$1>$L$2, "", IF(O$1=$L$2, 1, IF($L$2-O$1=$L$1-$M25, $L$3^($L$1-$M25), ($L$3*O26*P26/(O26+($L$3-1)*P26) )))) -> #DIV/0! | P25: =IF(P$1>$L$2, "", IF(P$1=$L$2, 1, IF($L$2-P$1=$L$1-$M25, $L$3^($L$1-$M25), ($L$3*P26*Q26/(P26+($L$3-1)*Q26) )))) -> #DIV/0! | Q25: =IF(Q$1>$L$2, "", IF(Q$1=$L$2, 1, IF($L$2-Q$1=$L$1-$M25, $L$3^($L$1-$M25), ($L$3*Q26*R26/(Q26+($L$3-1)*R26) )))) -> #DIV/0! | R25: =IF(R$1>$L$2, "", IF(R$1=$L$2, 1, IF($L$2-R$1=$L$1-$M25, $L$3^($L$1-$M25), ($L$3*R26*S26/(R26+($L$3-1)*S26) )))) -> 1 | S25: =IF(S$1>$L$2, "", IF(S$1=$L$2, 1, IF($L$2-S$1=$L$1-$M25, $L$3^($L$1-$M25), ($L$3*S26*T26/(S26+($L$3-1)*T26) )))) | T25: =IF(T$1>$L$2, "", IF(T$1=$L$2, 1, IF($L$2-T$1=$L$1-$M25, $L$3^($L$1-$M25), ($L$3*T26*U26/(T26+($L$3-1)*U26) )))) | U25: =IF(U$1>$L$2, "", IF(U$1=$L$2, 1, IF($L$2-U$1=$L$1-$M25, $L$3^($L$1-$M25), ($L$3*U26*V26/(U26+($L$3-1)*V26) )))) | ... DJ25: =IF(DJ$1>$L$2, "", IF(DJ$1=$L$2, 1, IF($L$2-DJ$1=$L$1-$M25, $L$3^($L$1-$M25), ($L$3*DJ26*DK26/(DJ26+($L$3-1)*DK26) ))))
A26: =MASANIELLO!#REF! -> #REF! | B26: =IF( OR(I25=$L$2,H25=1+$L$1-$L$2), "", IF(A26="l",0,IF(A26="w",1,"")) ) -> #VALUE! | C26: =IF(OR(I25>=$L$2,D25=""),"",IF(ISERROR((1-$L$3*INDEX($N$2:$DJ$101,H25+I25+2,I25+2)/(INDEX($N$2:$DJ$101,H25+I25+2,I25+1)+($L$3-1)*(INDEX($N$2:$DJ$101,H25+I25+2,I25+2))))*$F25), $F25, (1-$L$3*INDEX($N$2:$DJ$101,H25+I25+2,I25+2)/(INDEX($N$2:$DJ$101,H25+I25+2,I25+1)+($L$3-1)*(INDEX($N$2:$DJ$101,H25+I25+2,I25+2))))*$F25 ) ) -> #VALUE! | D26: =IF(I25>=$L$2,"",IF(B26="", "", C26*($L$3-1)*B26) ) -> #VALUE! | E26: =IF(B26="","",( D26-(IF((D26+F25)<=G25, D26, (G25-F25) )) )*(100-$L$5)/100 ) -> #VALUE! | F26: =IF(I25>=$L$2,"",IF(B26="", "", IF(B26=0, F25-C26, IF( ((F25+D26)-G25)>=0, F25+(G25-F25)+((D26-(G25-F25))*$L$5/100), F25+D26 ) )) ) -> #VALUE! | G26: =IF(F26>G25, F26, G25) -> #VALUE! | H26: =IF( $L$4=0, IF(I25+B26=$L$2,0,IF(B26=0,H25+1,H25)), IF( F26>=G25, 0, IF(B26=0,H25+1,H25) ) ) -> #VALUE! | I26: =IF( $L$4=0, IF(I25+B26=$L$2,0,IF(B26=1,I25+1,I25)), IF( F26>=G25, 0, IF(B26=1,I25+1,I25) ) ) -> #VALUE! | J26: =IF( B26="", "", IF( ISERROR((B26+I25)/(H25+I25+1)), 0, (B26+I25)/(H25+I25+1) ) ) -> #VALUE! | M26: =IF(M25<($L$1-1),M25+1) -> FALSE | N26: =IF(N$1>$L$2, "", IF(N$1=$L$2, 1, IF($L$2-N$1=$L$1-$M26, $L$3^($L$1-$M26), ($L$3*N27*O27/(N27+($L$3-1)*O27) )))) -> #DIV/0! | O26: =IF(O$1>$L$2, "", IF(O$1=$L$2, 1, IF($L$2-O$1=$L$1-$M26, $L$3^($L$1-$M26), ($L$3*O27*P27/(O27+($L$3-1)*P27) )))) -> #DIV/0! | P26: =IF(P$1>$L$2, "", IF(P$1=$L$2, 1, IF($L$2-P$1=$L$1-$M26, $L$3^($L$1-$M26), ($L$3*P27*Q27/(P27+($L$3-1)*Q27) )))) -> #DIV/0! | Q26: =IF(Q$1>$L$2, "", IF(Q$1=$L$2, 1, IF($L$2-Q$1=$L$1-$M26, $L$3^($L$1-$M26), ($L$3*Q27*R27/(Q27+($L$3-1)*R27) )))) -> #DIV/0! | R26: =IF(R$1>$L$2, "", IF(R$1=$L$2, 1, IF($L$2-R$1=$L$1-$M26, $L$3^($L$1-$M26), ($L$3*R27*S27/(R27+($L$3-1)*S27) )))) -> 1 | S26: =IF(S$1>$L$2, "", IF(S$1=$L$2, 1, IF($L$2-S$1=$L$1-$M26, $L$3^($L$1-$M26), ($L$3*S27*T27/(S27+($L$3-1)*T27) )))) | T26: =IF(T$1>$L$2, "", IF(T$1=$L$2, 1, IF($L$2-T$1=$L$1-$M26, $L$3^($L$1-$M26), ($L$3*T27*U27/(T27+($L$3-1)*U27) )))) | U26: =IF(U$1>$L$2, "", IF(U$1=$L$2, 1, IF($L$2-U$1=$L$1-$M26, $L$3^($L$1-$M26), ($L$3*U27*V27/(U27+($L$3-1)*V27) )))) | ... DJ26: =IF(DJ$1>$L$2, "", IF(DJ$1=$L$2, 1, IF($L$2-DJ$1=$L$1-$M26, $L$3^($L$1-$M26), ($L$3*DJ27*DK27/(DJ27+($L$3-1)*DK27) ))))
A27: =MASANIELLO!#REF! -> #REF! | B27: =IF( OR(I26=$L$2,H26=1+$L$1-$L$2), "", IF(A27="l",0,IF(A27="w",1,"")) ) -> #VALUE! | C27: =IF(OR(I26>=$L$2,D26=""),"",IF(ISERROR((1-$L$3*INDEX($N$2:$DJ$101,H26+I26+2,I26+2)/(INDEX($N$2:$DJ$101,H26+I26+2,I26+1)+($L$3-1)*(INDEX($N$2:$DJ$101,H26+I26+2,I26+2))))*$F26), $F26, (1-$L$3*INDEX($N$2:$DJ$101,H26+I26+2,I26+2)/(INDEX($N$2:$DJ$101,H26+I26+2,I26+1)+($L$3-1)*(INDEX($N$2:$DJ$101,H26+I26+2,I26+2))))*$F26 ) ) -> #VALUE! | D27: =IF(I26>=$L$2,"",IF(B27="", "", C27*($L$3-1)*B27) ) -> #VALUE! | E27: =IF(B27="","",( D27-(IF((D27+F26)<=G26, D27, (G26-F26) )) )*(100-$L$5)/100 ) -> #VALUE! | F27: =IF(I26>=$L$2,"",IF(B27="", "", IF(B27=0, F26-C27, IF( ((F26+D27)-G26)>=0, F26+(G26-F26)+((D27-(G26-F26))*$L$5/100), F26+D27 ) )) ) -> #VALUE! | G27: =IF(F27>G26, F27, G26) -> #VALUE! | H27: =IF( $L$4=0, IF(I26+B27=$L$2,0,IF(B27=0,H26+1,H26)), IF( F27>=G26, 0, IF(B27=0,H26+1,H26) ) ) -> #VALUE! | I27: =IF( $L$4=0, IF(I26+B27=$L$2,0,IF(B27=1,I26+1,I26)), IF( F27>=G26, 0, IF(B27=1,I26+1,I26) ) ) -> #VALUE! | J27: =IF( B27="", "", IF( ISERROR((B27+I26)/(H26+I26+1)), 0, (B27+I26)/(H26+I26+1) ) ) -> #VALUE! | M27: =IF(M26<($L$1-1),M26+1) -> FALSE | N27: =IF(N$1>$L$2, "", IF(N$1=$L$2, 1, IF($L$2-N$1=$L$1-$M27, $L$3^($L$1-$M27), ($L$3*N28*O28/(N28+($L$3-1)*O28) )))) -> #DIV/0! | O27: =IF(O$1>$L$2, "", IF(O$1=$L$2, 1, IF($L$2-O$1=$L$1-$M27, $L$3^($L$1-$M27), ($L$3*O28*P28/(O28+($L$3-1)*P28) )))) -> #DIV/0! | P27: =IF(P$1>$L$2, "", IF(P$1=$L$2, 1, IF($L$2-P$1=$L$1-$M27, $L$3^($L$1-$M27), ($L$3*P28*Q28/(P28+($L$3-1)*Q28) )))) -> #DIV/0! | Q27: =IF(Q$1>$L$2, "", IF(Q$1=$L$2, 1, IF($L$2-Q$1=$L$1-$M27, $L$3^($L$1-$M27), ($L$3*Q28*R28/(Q28+($L$3-1)*R28) )))) -> #DIV/0! | R27: =IF(R$1>$L$2, "", IF(R$1=$L$2, 1, IF($L$2-R$1=$L$1-$M27, $L$3^($L$1-$M27), ($L$3*R28*S28/(R28+($L$3-1)*S28) )))) -> 1 | S27: =IF(S$1>$L$2, "", IF(S$1=$L$2, 1, IF($L$2-S$1=$L$1-$M27, $L$3^($L$1-$M27), ($L$3*S28*T28/(S28+($L$3-1)*T28) )))) | T27: =IF(T$1>$L$2, "", IF(T$1=$L$2, 1, IF($L$2-T$1=$L$1-$M27, $L$3^($L$1-$M27), ($L$3*T28*U28/(T28+($L$3-1)*U28) )))) | U27: =IF(U$1>$L$2, "", IF(U$1=$L$2, 1, IF($L$2-U$1=$L$1-$M27, $L$3^($L$1-$M27), ($L$3*U28*V28/(U28+($L$3-1)*V28) )))) | ... DJ27: =IF(DJ$1>$L$2, "", IF(DJ$1=$L$2, 1, IF($L$2-DJ$1=$L$1-$M27, $L$3^($L$1-$M27), ($L$3*DJ28*DK28/(DJ28+($L$3-1)*DK28) ))))
A28: =MASANIELLO!#REF! -> #REF! | B28: =IF( OR(I27=$L$2,H27=1+$L$1-$L$2), "", IF(A28="l",0,IF(A28="w",1,"")) ) -> #VALUE! | C28: =IF(OR(I27>=$L$2,D27=""),"",IF(ISERROR((1-$L$3*INDEX($N$2:$DJ$101,H27+I27+2,I27+2)/(INDEX($N$2:$DJ$101,H27+I27+2,I27+1)+($L$3-1)*(INDEX($N$2:$DJ$101,H27+I27+2,I27+2))))*$F27), $F27, (1-$L$3*INDEX($N$2:$DJ$101,H27+I27+2,I27+2)/(INDEX($N$2:$DJ$101,H27+I27+2,I27+1)+($L$3-1)*(INDEX($N$2:$DJ$101,H27+I27+2,I27+2))))*$F27 ) ) -> #VALUE! | D28: =IF(I27>=$L$2,"",IF(B28="", "", C28*($L$3-1)*B28) ) -> #VALUE! | E28: =IF(B28="","",( D28-(IF((D28+F27)<=G27, D28, (G27-F27) )) )*(100-$L$5)/100 ) -> #VALUE! | F28: =IF(I27>=$L$2,"",IF(B28="", "", IF(B28=0, F27-C28, IF( ((F27+D28)-G27)>=0, F27+(G27-F27)+((D28-(G27-F27))*$L$5/100), F27+D28 ) )) ) -> #VALUE! | G28: =IF(F28>G27, F28, G27) -> #VALUE! | H28: =IF( $L$4=0, IF(I27+B28=$L$2,0,IF(B28=0,H27+1,H27)), IF( F28>=G27, 0, IF(B28=0,H27+1,H27) ) ) -> #VALUE! | I28: =IF( $L$4=0, IF(I27+B28=$L$2,0,IF(B28=1,I27+1,I27)), IF( F28>=G27, 0, IF(B28=1,I27+1,I27) ) ) -> #VALUE! | J28: =IF( B28="", "", IF( ISERROR((B28+I27)/(H27+I27+1)), 0, (B28+I27)/(H27+I27+1) ) ) -> #VALUE! | M28: =IF(M27<($L$1-1),M27+1) -> FALSE | N28: =IF(N$1>$L$2, "", IF(N$1=$L$2, 1, IF($L$2-N$1=$L$1-$M28, $L$3^($L$1-$M28), ($L$3*N29*O29/(N29+($L$3-1)*O29) )))) -> #DIV/0! | O28: =IF(O$1>$L$2, "", IF(O$1=$L$2, 1, IF($L$2-O$1=$L$1-$M28, $L$3^($L$1-$M28), ($L$3*O29*P29/(O29+($L$3-1)*P29) )))) -> #DIV/0! | P28: =IF(P$1>$L$2, "", IF(P$1=$L$2, 1, IF($L$2-P$1=$L$1-$M28, $L$3^($L$1-$M28), ($L$3*P29*Q29/(P29+($L$3-1)*Q29) )))) -> #DIV/0! | Q28: =IF(Q$1>$L$2, "", IF(Q$1=$L$2, 1, IF($L$2-Q$1=$L$1-$M28, $L$3^($L$1-$M28), ($L$3*Q29*R29/(Q29+($L$3-1)*R29) )))) -> #DIV/0! | R28: =IF(R$1>$L$2, "", IF(R$1=$L$2, 1, IF($L$2-R$1=$L$1-$M28, $L$3^($L$1-$M28), ($L$3*R29*S29/(R29+($L$3-1)*S29) )))) -> 1 | S28: =IF(S$1>$L$2, "", IF(S$1=$L$2, 1, IF($L$2-S$1=$L$1-$M28, $L$3^($L$1-$M28), ($L$3*S29*T29/(S29+($L$3-1)*T29) )))) | T28: =IF(T$1>$L$2, "", IF(T$1=$L$2, 1, IF($L$2-T$1=$L$1-$M28, $L$3^($L$1-$M28), ($L$3*T29*U29/(T29+($L$3-1)*U29) )))) | U28: =IF(U$1>$L$2, "", IF(U$1=$L$2, 1, IF($L$2-U$1=$L$1-$M28, $L$3^($L$1-$M28), ($L$3*U29*V29/(U29+($L$3-1)*V29) )))) | ... DJ28: =IF(DJ$1>$L$2, "", IF(DJ$1=$L$2, 1, IF($L$2-DJ$1=$L$1-$M28, $L$3^($L$1-$M28), ($L$3*DJ29*DK29/(DJ29+($L$3-1)*DK29) ))))
